Workbook
Name all_subsystems: '[1]Служебный ОП'!$A$3:$A$22
Name all_subsystems: '[1]Служебный ОП'!$A$3:$A$22
Name all_subsystems: '[2]Служебный ОП'!$A$3:$A$22
Name ASUTP_APMDZ: '[3]Служебный АСУТП'!$N$2:$N$3
Name ASUTP_APMDZ: 'Служебный АСУТП'!$N$2:$N$3
Name ASUTP_APT: '[4]Служебный АСУТП'!$Z$2:$Z$4
Name ASUTP_APT: '[3]Служебный АСУТП'!$AA$2:$AA$4
Name ASUTP_APT: '[4]Служебный АСУТП'!$Z$2:$Z$4
Name ASUTP_APT: 'Служебный АСУТП'!$AA$2:$AA$4
Name ASUTP_AVZ: '[5]Служебный АСУТП'!$E$2
Name ASUTP_AVZ: '[6]Служебный АСУТП'!$E$2:$E$9
Name ASUTP_AVZ: '[4]Служебный АСУТП'!$E$2:$E$9
Name ASUTP_AVZ: '[7]Служебный АСУТП'!$E$2:$E$5
Name ASUTP_AVZ: '[3]Служебный АСУТП'!$E$2:$E$9
Name ASUTP_AVZ: '[5]Служебный АСУТП'!$E$2
Name ASUTP_AVZ: '[6]Служебный АСУТП'!$E$2:$E$9
Name ASUTP_AVZ: '[8]Служебный АСУТП'!$E$2:$E$5
Name ASUTP_AVZ: 'Служебный АСУТП'!$E$2:$E$9
Name ASUTP_AZ: '[5]Служебный АСУТП'!$J$2:$J$3
Name ASUTP_AZ: '[6]Служебный АСУТП'!$J$2:$J$6
Name ASUTP_AZ: '[4]Служебный АСУТП'!$J$2:$J$6
Name ASUTP_AZ: '[7]Служебный АСУТП'!$J$2:$J$5
Name ASUTP_AZ: '[3]Служебный АСУТП'!$J$2:$J$6
Name ASUTP_AZ: '[5]Служебный АСУТП'!$J$2:$J$3
Name ASUTP_AZ: '[6]Служебный АСУТП'!$J$2:$J$6
Name ASUTP_AZ: '[8]Служебный АСУТП'!$J$2:$J$5
Name ASUTP_AZ: 'Служебный АСУТП'!$J$2:$J$6
Name ASUTP_CONFIG: '[4]Служебный АСУТП'!$W$2
Name ASUTP_CONFIG: '[3]Служебный АСУТП'!$X$2
Name ASUTP_CONFIG: '[4]Служебный АСУТП'!$W$2
Name ASUTP_CONFIG: 'Служебный АСУТП'!$X$2
Name ASUTP_DAM: '[5]Служебный АСУТП'!$O$2
Name ASUTP_DAM: '[6]Служебный АСУТП'!$O$2:$O$5
Name ASUTP_DAM: '[4]Служебный АСУТП'!$O$2:$O$5
Name ASUTP_DAM: '[7]Служебный АСУТП'!$O$2:$O$7
Name ASUTP_DAM: '[3]Служебный АСУТП'!$P$2:$P$5
Name ASUTP_DAM: '[5]Служебный АСУТП'!$O$2
Name ASUTP_DAM: '[6]Служебный АСУТП'!$O$2:$O$5
Name ASUTP_DAM: '[8]Служебный АСУТП'!$O$2:$O$7
Name ASUTP_DAM: 'Служебный АСУТП'!$P$2:$P$5
Name ASUTP_DCAP: '[4]Служебный АСУТП'!$V$2:$V$4
Name ASUTP_DCAP: '[3]Служебный АСУТП'!$W$2:$W$4
Name ASUTP_DCAP: '[4]Служебный АСУТП'!$V$2:$V$4
Name ASUTP_DCAP: 'Служебный АСУТП'!$W$2:$W$4
Name ASUTP_EDR: '[4]Служебный АСУТП'!$AC$2:$AC$3
Name ASUTP_EDR: '[3]Служебный АСУТП'!$AD$2:$AD$3
Name ASUTP_EDR: '[4]Служебный АСУТП'!$AC$2:$AC$3
Name ASUTP_EDR: 'Служебный АСУТП'!$AD$2:$AD$3
Name ASUTP_GOSSOPKA: '[4]Служебный АСУТП'!$T$2:$T$3
Name ASUTP_GOSSOPKA: '[3]Служебный АСУТП'!$U$2:$U$3
Name ASUTP_GOSSOPKA: '[4]Служебный АСУТП'!$T$2:$T$3
Name ASUTP_GOSSOPKA: 'Служебный АСУТП'!$U$2:$U$3
Name ASUTP_IDS: '[5]Служебный АСУТП'!$L$2:$L$4
Name ASUTP_IDS: '[6]Служебный АСУТП'!$L$2:$L$4
Name ASUTP_IDS: '[4]Служебный АСУТП'!$L$2:$L$4
Name ASUTP_IDS: '[7]Служебный АСУТП'!$L$2:$L$4
Name ASUTP_IDS: '[3]Служебный АСУТП'!$L$2:$L$4
Name ASUTP_IDS: '[5]Служебный АСУТП'!$L$2:$L$4
Name ASUTP_IDS: '[6]Служебный АСУТП'!$L$2:$L$4
Name ASUTP_IDS: '[8]Служебный АСУТП'!$L$2:$L$4

Sheet Информация
A1: Заявка на бюджетирование проекта
A2: № п.п. | B2: Вопрос | C2: Значение
A3: 1 | B3: ФИО разработчика спецификации
A4: 2 | B4: ФИО ответственного за проект
A5: 3 | B5: Дата, когда необходим ответ
A6: 4 | B6: Цепочка поставки. Выбрать из списка: Для внутренних нужд - для использования внутри Солар, без права передачи третьим лицам и без права использования для выгодоприобретения. Перепродажа - передача права конечному заказчику. Услуги третьим лицам - покупка на баланс Солар с правом оказания сервисов и использования продукта с целью выгодоприобретения. Сервисы - покупка на баланс Солар для обеспечения работы каких либо сервисов без передачи продукта (в любом виде) конечному заказчику или любому другому третьему лицу.
A7: 5 | B7: Название конечного заказчика (Если для внутренних нужд, указывать Солар)
A8: 6 | B8: Название проекта
A9: 7 | B9: Номер пресейла, если есть
A10: 8 | B10: Название участников - партнер/партнеры (указать), если есть
A11: 9 | B11: Ссылка на конкурс, если есть
A12: 10 | B12: Планируемая дата подачи в конкурс, если известна
A13: 11 | B13: Прогнозируемая дата поставки по конкурсу, если известна
A14: 12 | B14: Адрес доставки
A15: 13 | B15: Формы для регистрации проектов по вендорам выложены в папке по ссылке: | C15: Ссылка будет позднее
A16: 14 | B16: Если формы нет в папке, просьба заполнить следующие поля.
A17: 15 | B17: ИНН конечного заказчика
A18: 16 | B18: КПП конечного заказчика
A19: 17 | B19: ФИО контактного лица заказчика
A20: 18 | B20: Должность контактного лица заказчика
A21: 19 | B21: Телефон контактного лица заказчика
A22: 20 | B22: Корпоративный адрес электронной почты контактного лица заказчика
A23: 21 | B23: Сайт организации

Sheet Файл оценки
F1: Трз по ролям
A2: Заказчик | D2: Сумарные ТРз | E2: Ответственное подразделение | F2: И | G2: СИ | H2: ВИ | I2: ГИП | L2: Заполнять командировки с комментарием учтены ли дни на дорогу в столбце H, если учтены писать кол-во дней в дороге, если так же добавляются Трз на предварительную подготовку к выезду так же писать комментарий. Например: Командировка на Завод N1, учтено в расчете 2 дня на дорогу туда-обратно, 1 день на подготовку к выезду, 4 дня работа на площадке = итого 6 дней (с дорогой 2 дня)
A3: Наименование сервиса или услуги | D3: =SUM(D4:D8) -> 103.10938 | E3: =IF(D3,IF(D4=MAX(D4:D8),B4,IF(D5=MAX(D4:D8),B5,IF(D6=MAX(D4:D8),B6,IF(D7=MAX(D4:D8),B7,IF(D8=MAX(D4:D8),B8))))),"") -> ОКиА
A4: Ответственный исполнитель | B4: ОКиА | D4: =SUMIF($D$14:$D$251,"=Инженер ОК",$E$14:$E$251) + SUMIF($D$14:$D$251,"Старший инженер ОК",$E$14:$E$251)+ SUMIF($D$14:$D$251,"Ведущий инженер ОК",$E$14:$E$251)+ SUMIF($D$14:$D$251,"ГИП ОК",$E$14:$E$251) -> 82.7375 | F4: =SUMIF($D$14:$D$251,"Инженер ОК",$E$14:$E$251) -> 38.0725 | G4: =SUMIF($D$14:$D$251,"Старший инженер ОК",$E$14:$E$251) -> 30.779813 | H4: =SUMIF($D$14:$D$251,"Ведущий инженер ОК",$E$14:$E$251) -> 13.885188 | I4: =SUMIF($D$14:$D$251,"ГИП ОК",$E$14:$E$251) -> 0
B5: ОП | D5: =SUMIF($D$14:$D$251,"Инженер ОП",$E$14:$E$251) + SUMIF($D$14:$D$251,"Старший инженер ОП",$E$14:$E$251) + SUMIF($D$14:$D$251,"Ведущий инженер ОП",$E$14:$E$251)+ SUMIF($D$14:$D$251,"ГИП ОП",$E$14:$E$251) -> 6.790625 | F5: =SUMIF($D$14:$D$251,"Инженер ОП",$E$14:$E$251) -> 0 | G5: =SUMIF($D$14:$D$251,"Старший инженер ОП",$E$14:$E$251) -> 0 | H5: =SUMIF($D$14:$D$251,"Ведущий инженер ОП",$E$14:$E$251) -> 0 | I5: =SUMIF($D$14:$D$251,"ГИП ОП",$E$14:$E$251) -> 6.790625
B6: ОВ | D6: =SUMIF($D$14:$D$251,"=Инженер ОВ",$E$14:$E$251) + SUMIF($D$14:$D$251,"Старший инженер ОВ",$E$14:$E$251) + SUMIF($D$14:$D$251,"Ведущий инженер ОВ",$E$14:$E$251) + SUMIF($D$14:$D$251,"ГИП ОВ",$E$14:$E$251) -> 0 | F6: =SUMIF($D$14:$D$251,"Инженер ОВ",$E$14:$E$251) -> 0 | G6: =SUMIF($D$14:$D$251,"Старший инженер ОВ",$E$14:$E$251) -> 0 | H6: =SUMIF($D$14:$D$251,"Ведущий инженер ОВ",$E$14:$E$251) -> 0 | I6: =SUMIF($D$14:$D$251,"ГИП ОВ",$E$14:$E$251) -> 0
B7: Нормоконтроль | D7: =SUMIF($D$14:$D$251,"=Нормоконтроль ОП",$E$14:$E$251) -> 0
B8: РП | D8: =SUMIF($D$14:$D$251,"Администратор проектов",$E$14:$E$251)+SUMIF($D$14:$D$251,"Ведущий РП",$E$14:$E$251)+SUMIF($D$14:$D$251,"РП",$E$14:$E$251) -> 13.58125
C9: * - желтой заливкой обозначен ТО
D10: =IF(SUM(D4:D6)>500,(IF(SUM(D4:D6)>500,"Согласовать c Директором ЦКП","")),(IF(AND(SUM(D4:D6)>100,SUM(D4:D6)<500),CONCATENATE("Согласовать с руководителем ",IF(D3,IF(D4=MAX(D4:D8),B4,IF(D5=MAX(D4:D8),B5,IF(D6=MAX(D4:D8),B6,IF(D7=MAX(D4:D8),B7,IF(D8=MAX(D4:D8),B8))))),""))))) -> FALSE
D11: =IF(A253<>"","У расчета есть ограничения","")
F12: Командировки
A13: Наименование работ по ТЗ | B13: Подэтапы для САДКО | C13: Результаты этапа (документация/детализация) | D13: Специалист | E13: Количество ч\д | F13: Количество человек | G13: Количество суток в одной поездке на одного человека (с учетом дороги) | H13: Количество поездок | I13: Куда | J13: Трудощатраты в командировке | K13: Длительность этапа раб.дни | L13: Примечание | R13: ОП | S13: ОК | T13: ОВ
A14: 1. Обследование/аудит по направлению "Безопасность КИИ" | B14: 1.1 Подготовка опросных листов и методики для аудита/обследования | C14: Методика проведения аудита/обследования; Заполненные ОЛ по аудиту/обследованию; | D14: Инженер ОК | E14: =IF(D14="Инженер ОК",ТрЗ_ОКиА!$K$28,IF(D14="Старший инженер ОК",ТрЗ_ОКиА!$L$28,IF(D14="Ведущий инженер ОК",ТрЗ_ОКиА!$M$28,""))) -> 0.6 | K14: *Экспертно определяем и указываем длительность этапа | M14: Очное/заочное обследование площадок Заполненные опросные листы | Q14: 1 | R14: 0 | S14: 1.45 | T14: 0
D15: Старший инженер ОК | E15: =IF(D15="Инженер ОК",ТрЗ_ОКиА!$K$28,IF(D15="Старший инженер ОК",ТрЗ_ОКиА!$L$28,IF(D15="Ведущий инженер ОК",ТрЗ_ОКиА!$M$28,""))) -> 0.3 | M15: ОП | N15: 0 | O15: 15 | Q15: 2 | R15: 0 | S15: 0.25 | T15: 0
D16: Ведущий инженер ОК | E16: =IF(D16="Инженер ОК",ТрЗ_ОКиА!$K$28,IF(D16="Старший инженер ОК",ТрЗ_ОКиА!$L$28,IF(D16="Ведущий инженер ОК",ТрЗ_ОКиА!$M$28,""))) -> 0.1 | M16: ОК | N16: 22
D17: Инженер ОП | M17: ОВ | N17: 0
D18: Инженер ОП
D19: Старший инженер ОП | M19: Отчет по обследованию
D20: Старший инженер ОП | M20: ОП | N20: 0 | O20: 11
D21: Ведущий инженер ОП
D22: Ведущий инженер ОП | M22: ОК | N22: 15,4
B23: 1.2 Очное/заочное обследование площадок | C23: Заполненные ОЛ по аудиту/обследованию; | D23: Инженер ОК | E23: =ROUNDUP(IF(D23="Инженер ОК",ТрЗ_ОКиА!$K$31,IF(D23="Старший инженер ОК",ТрЗ_ОКиА!$L$31,IF(D23="Ведущий инженер ОК",ТрЗ_ОКиА!$M$31,""))),0) -> 4 | F23: 1 | G23: 4.1 | H23: 1 | J23: =F23*G23*H23 -> 4.1 | M23: ОВ | N23: 0
D24: Старший инженер ОК | E24: =ROUNDUP(IF(D24="Инженер ОК",ТрЗ_ОКиА!$K$31,IF(D24="Старший инженер ОК",ТрЗ_ОКиА!$L$31,IF(D24="Ведущий инженер ОК",ТрЗ_ОКиА!$M$31,""))),0) -> 4 | F24: 1 | G24: 3.2 | H24: 1 | J24: =F24*G24*H24 -> 3.2
D25: Ведущий инженер ОК | E25: =ROUNDUP(IF(D25="Инженер ОК",ТрЗ_ОКиА!$K$31,IF(D25="Старший инженер ОК",ТрЗ_ОКиА!$L$31,IF(D25="Ведущий инженер ОК",ТрЗ_ОКиА!$M$31,""))),0) -> 2 | F25: 1 | G25: 2 | H25: 1 | J25: =F25*G25*H25 -> 2 | M25: ОП | N25: 0
D26: Инженер ОП | M26: ОК | N26: 0
D27: Старший инженер ОП
D28: Ведущий инженер ОП | M28: ОВ | N28: 0
D29: Нормоконтроль ОП | L29: НК=Инженер
B30: 1.3 Разработка отчета по обследованию/аудиту | C30: Отчет по результатам аудита/обследования | D30: Инженер ОК | E30: =IF(D30="Инженер ОК",ТрЗ_ОКиА!$K$35,IF(D30="Старший инженер ОК",ТрЗ_ОКиА!$L$35,IF(D30="Ведущий инженер ОК",ТрЗ_ОКиА!$M$35,""))) -> 4 | M30: ОВ | N30: 0
D31: Старший инженер ОК | E31: =IF(D31="Инженер ОК",ТрЗ_ОКиА!$K$35,IF(D31="Старший инженер ОК",ТрЗ_ОКиА!$L$35,IF(D31="Ведущий инженер ОК",ТрЗ_ОКиА!$M$35,""))) -> 3.2 | M31: Перечень угроз и нарушителей
D32: Ведущий инженер ОК | E32: =IF(D32="Инженер ОК",ТрЗ_ОКиА!$K$35,IF(D32="Старший инженер ОК",ТрЗ_ОКиА!$L$35,IF(D32="Ведущий инженер ОК",ТрЗ_ОКиА!$M$35,""))) -> 0.8 | M32: ОП | N32: 0
D33: Инженер ОП | M33: ОК | N33: 0
D34: Старший инженер ОП
D35: Ведущий инженер ОП | M35: ОВ | N35: 0
D36: Нормоконтроль ОП | L36: НК=Инженер
B37: 1.3 Техническое управление проектом | D37: ГИП ОП | E37: =SUM(E14:E36)*0.1 -> 1.9 | M37: ЧМУиН
B38: 1.4 Администрирование проекта | D38: Ведущий РП | E38: =SUM(E14:E36)*0.2 -> 3.8 | M38: ОП | N38: 0
A39: 1. Обследование/аудит по направлению "Безопасность ПДн" | B39: 1.1 Подготовка опросных листов и методики для аудита/обследования | C39: Методика проведения аудита/обследования; Заполненные ОЛ по аудиту/обследованию; | D39: Инженер ОК | E39: =IF(D39="Инженер ОК",ТрЗ_ОКиА!$K$92,IF(D39="Старший инженер ОК",ТрЗ_ОКиА!$L$92,IF(D39="Ведущий инженер ОК",ТрЗ_ОКиА!$M$92,""))) -> 0.6 | K39: *Экспертно определяем и указываем длительность этапа
D40: Старший инженер ОК | E40: =IF(D40="Инженер ОК",ТрЗ_ОКиА!$K$92,IF(D40="Старший инженер ОК",ТрЗ_ОКиА!$L$92,IF(D40="Ведущий инженер ОК",ТрЗ_ОКиА!$M$92,""))) -> 0.3 | M40: ОП | N40: 0
...

Sheet ТрЗ_ОП
B1: Исходные данные: | C1: Исходные данные | D1: Выбор набора СрЗИ (КИИ, ИСПДн, ГИС) | F1: Значения | G1: Командировки | W1: Документы: | AE1: номер столбца | AF1: простой Пресейл | AG1: обычный Пресейл | AH1: сложный Пресейл | AI1: простое ЭП | AJ1: обычное ЭП | AK1: сложное ЭП | AL1: простое ТРП | AM1: обычное ТРП | AN1: сложное ТРП | AO1: простое ТП | AP1: обычное ТП | AQ1: сложное ТП
B2: Тип разрабатываемой документации | D2: Уровень зрелости | F2: =W5 -> ТРП | G2: Кол-во площадок | H2: 666 | I2: количество | V2: 2 | W2: 2 | AE2: =IF(A11,MATCH(C11,'Документы АСУТП'!$E$3:$CI$3,0),"") + 4 -> 5 | AF2: =INDIRECT(ADDRESS(107,AE2,1,1,"Документы АСУТП")) -> 5 | AG2: =INDIRECT(ADDRESS(108,AE2,1,1,"Документы АСУТП")) -> 1 | AH2: =INDIRECT(ADDRESS(109,AE2,1,1,"Документы АСУТП")) -> 1 | AI2: =INDIRECT(ADDRESS(110,$AE2,1,1,"Документы АСУТП")) -> 3.5 | AJ2: =INDIRECT(ADDRESS(111,$AE2,1,1,"Документы АСУТП")) -> 2 | AK2: =INDIRECT(ADDRESS(112,$AE2,1,1,"Документы АСУТП")) -> 2.5 | AL2: =INDIRECT(ADDRESS(113,$AE2,1,1,"Документы АСУТП")) -> 44.25 | AM2: =INDIRECT(ADDRESS(114,$AE2,1,1,"Документы АСУТП")) -> 17.5 | AN2: =INDIRECT(ADDRESS(115,$AE2,1,1,"Документы АСУТП")) -> 28 | AO2: =INDIRECT(ADDRESS(116,$AE2,1,1,"Документы АСУТП")) -> 11.25 | AP2: =INDIRECT(ADDRESS(117,$AE2,1,1,"Документы АСУТП")) -> 10 | AQ2: =INDIRECT(ADDRESS(118,$AE2,1,1,"Документы АСУТП")) -> 15.5
B3: Техническая грамотность Заказчика* | D3: ГИС | F3: =W42 -> 1 | G3: Геораспределенность | H3: Нет | I3: да/нет
B4: Лояльность Заказчика** | D4: ИСПДн | F4: =W41 -> 1 | G4: Кол-во систем | H4: 3 | I4: количество
B5: Архитектура СОИБ | D5: КИИ | F5: =W13 -> 1 | G5: масштаб систем | H5: Маленькая | I5: маленька/средняя/большая | W5: =INDEX('Служебный АСУТП'!C12:C19,MATCH(W2,'Служебный АСУТП'!D12:D19,0)) -> ТРП | AE5: =IF(A12,MATCH(C12,'Документы АСУТП'!$E$3:$CU$3,0),"") + 4 -> 14 | AF5: =INDIRECT(ADDRESS(107,AE5,1,1,"Документы АСУТП")) -> 3 | AG5: =INDIRECT(ADDRESS(108,AE5,1,1,"Документы АСУТП")) -> 2 | AH5: =INDIRECT(ADDRESS(109,AE5,1,1,"Документы АСУТП")) -> 2 | AI5: =INDIRECT(ADDRESS(110,$AE5,1,1,"Документы АСУТП")) -> 3.5 | AJ5: =INDIRECT(ADDRESS(111,$AE5,1,1,"Документы АСУТП")) -> 3 | AK5: =INDIRECT(ADDRESS(112,$AE5,1,1,"Документы АСУТП")) -> 5 | AL5: =INDIRECT(ADDRESS(113,$AE5,1,1,"Документы АСУТП")) -> 57.25 | AM5: =INDIRECT(ADDRESS(114,$AE5,1,1,"Документы АСУТП")) -> 25.5 | AN5: =INDIRECT(ADDRESS(115,$AE5,1,1,"Документы АСУТП")) -> 43.5 | AO5: =INDIRECT(ADDRESS(116,$AE5,1,1,"Документы АСУТП")) -> 16.75 | AP5: =INDIRECT(ADDRESS(117,$AE5,1,1,"Документы АСУТП")) -> 12.5 | AQ5: =INDIRECT(ADDRESS(118,$AE5,1,1,"Документы АСУТП")) -> 20.5
B6: Уровень типизации проекта | C6: =INDEX('Служебный АСУТП'!C23:C25,MATCH(W7,'Служебный АСУТП'!D23:D25,0)) -> Обычный | F6: =W7 -> 2 | G6: тип проекта | H6: ЭП | I6: ЭП/ТРП/Пресейл/ТП | W6: Типизация | AE6: =IF(A13,MATCH(C13,'Документы АСУТП'!$E$3:$CU$3,0),"") + 4 -> #VALUE! | AF6: =INDIRECT(ADDRESS(107,AE6,1,1,"Документы АСУТП")) -> #VALUE! | AG6: =INDIRECT(ADDRESS(108,AE6,1,1,"Документы АСУТП")) -> #VALUE! | AH6: =INDIRECT(ADDRESS(109,AE6,1,1,"Документы АСУТП")) -> #VALUE! | AI6: =INDIRECT(ADDRESS(110,$AE6,1,1,"Документы АСУТП")) -> #VALUE! | AJ6: =INDIRECT(ADDRESS(111,$AE6,1,1,"Документы АСУТП")) -> #VALUE! | AK6: =INDIRECT(ADDRESS(112,$AE6,1,1,"Документы АСУТП")) -> #VALUE! | AL6: =INDIRECT(ADDRESS(113,$AE6,1,1,"Документы АСУТП")) -> #VALUE! | AM6: =INDIRECT(ADDRESS(114,$AE6,1,1,"Документы АСУТП")) -> #VALUE! | AN6: =INDIRECT(ADDRESS(115,$AE6,1,1,"Документы АСУТП")) -> #VALUE! | AO6: =INDIRECT(ADDRESS(116,$AE6,1,1,"Документы АСУТП")) -> #VALUE! | AP6: =INDIRECT(ADDRESS(117,$AE6,1,1,"Документы АСУТП")) -> #VALUE! | AQ6: =INDIRECT(ADDRESS(118,$AE6,1,1,"Документы АСУТП")) -> #VALUE!
B7: *Тех грамотность: высокая - упрощает реализацию, т.к. Заказчик сможет принимать решения, согласовывать подходы и корректно и полноценно предоставлять ИД для проектирования | W7: 2 | AE7: =IF(A14,MATCH(C14,'Документы АСУТП'!$E$3:$CU$3,0),"") + 4 -> #VALUE! | AF7: =INDIRECT(ADDRESS(107,AE7,1,1,"Документы АСУТП")) -> #VALUE! | AG7: =INDIRECT(ADDRESS(108,AE7,1,1,"Документы АСУТП")) -> #VALUE! | AH7: =INDIRECT(ADDRESS(109,AE7,1,1,"Документы АСУТП")) -> #VALUE! | AI7: =INDIRECT(ADDRESS(110,$AE7,1,1,"Документы АСУТП")) -> #VALUE! | AJ7: =INDIRECT(ADDRESS(111,$AE7,1,1,"Документы АСУТП")) -> #VALUE! | AK7: =INDIRECT(ADDRESS(112,$AE7,1,1,"Документы АСУТП")) -> #VALUE! | AL7: =INDIRECT(ADDRESS(113,$AE7,1,1,"Документы АСУТП")) -> #VALUE! | AM7: =INDIRECT(ADDRESS(114,$AE7,1,1,"Документы АСУТП")) -> #VALUE! | AN7: =INDIRECT(ADDRESS(115,$AE7,1,1,"Документы АСУТП")) -> #VALUE! | AO7: =INDIRECT(ADDRESS(116,$AE7,1,1,"Документы АСУТП")) -> #VALUE! | AP7: =INDIRECT(ADDRESS(117,$AE7,1,1,"Документы АСУТП")) -> #VALUE! | AQ7: =INDIRECT(ADDRESS(118,$AE7,1,1,"Документы АСУТП")) -> #VALUE!
B8: ** Лояльность: высокая - упрощает реализацию, значит Заказчик лояльный и замечания будут конструктивные | W8: =INDEX('Служебный АСУТП'!C23:C25,MATCH(W7,'Служебный АСУТП'!D23:D25,0)) -> Обычный | AE8: =IF(A15,MATCH(C15,'Документы АСУТП'!$E$3:$CU$3,0),"") + 4 -> #VALUE! | AF8: =INDIRECT(ADDRESS(107,AE8,1,1,"Документы АСУТП")) -> #VALUE! | AG8: =INDIRECT(ADDRESS(108,AE8,1,1,"Документы АСУТП")) -> #VALUE! | AH8: =INDIRECT(ADDRESS(109,AE8,1,1,"Документы АСУТП")) -> #VALUE! | AI8: =INDIRECT(ADDRESS(110,$AE8,1,1,"Документы АСУТП")) -> #VALUE! | AJ8: =INDIRECT(ADDRESS(111,$AE8,1,1,"Документы АСУТП")) -> #VALUE! | AK8: =INDIRECT(ADDRESS(112,$AE8,1,1,"Документы АСУТП")) -> #VALUE! | AL8: =INDIRECT(ADDRESS(113,$AE8,1,1,"Документы АСУТП")) -> #VALUE! | AM8: =INDIRECT(ADDRESS(114,$AE8,1,1,"Документы АСУТП")) -> #VALUE! | AN8: =INDIRECT(ADDRESS(115,$AE8,1,1,"Документы АСУТП")) -> #VALUE! | AO8: =INDIRECT(ADDRESS(116,$AE8,1,1,"Документы АСУТП")) -> #VALUE! | AP8: =INDIRECT(ADDRESS(117,$AE8,1,1,"Документы АСУТП")) -> #VALUE! | AQ8: =INDIRECT(ADDRESS(118,$AE8,1,1,"Документы АСУТП")) -> #VALUE!
AA9: 1 | AE9: =IF(A16,MATCH(C16,'Документы АСУТП'!$E$3:$CU$3,0),"") + 4 -> #VALUE! | AF9: =INDIRECT(ADDRESS(107,AE9,1,1,"Документы АСУТП")) -> #VALUE! | AG9: =INDIRECT(ADDRESS(108,AE9,1,1,"Документы АСУТП")) -> #VALUE! | AH9: =INDIRECT(ADDRESS(109,AE9,1,1,"Документы АСУТП")) -> #VALUE! | AI9: =INDIRECT(ADDRESS(110,$AE9,1,1,"Документы АСУТП")) -> #VALUE! | AJ9: =INDIRECT(ADDRESS(111,$AE9,1,1,"Документы АСУТП")) -> #VALUE! | AK9: =INDIRECT(ADDRESS(112,$AE9,1,1,"Документы АСУТП")) -> #VALUE! | AL9: =INDIRECT(ADDRESS(113,$AE9,1,1,"Документы АСУТП")) -> #VALUE! | AM9: =INDIRECT(ADDRESS(114,$AE9,1,1,"Документы АСУТП")) -> #VALUE! | AN9: =INDIRECT(ADDRESS(115,$AE9,1,1,"Документы АСУТП")) -> #VALUE! | AO9: =INDIRECT(ADDRESS(116,$AE9,1,1,"Документы АСУТП")) -> #VALUE! | AP9: =INDIRECT(ADDRESS(117,$AE9,1,1,"Документы АСУТП")) -> #VALUE! | AQ9: =INDIRECT(ADDRESS(118,$AE9,1,1,"Документы АСУТП")) -> #VALUE!
B10: Применяемые подсистемы | D10: Параметр 1 | E10: Значение | F10: Параметр 2 | H10: Параметр 3 | I10: Значение | J10: Пресейл | K10: ЭП | L10: ТРП | M10: ТП | N10: Сумма (часы) | O10: Исходные параметры АСУТП | P10: Значения | T10: Трудозатраты АСУ ТП | W10: Значение | Y10: Значение | AA10: 1 | AE10: =IF(A17,MATCH(C17,'Документы АСУТП'!$E$3:$CU$3,0),"") + 4 -> #VALUE! | AF10: =INDIRECT(ADDRESS(107,AE10,1,1,"Документы АСУТП")) -> #VALUE! | AG10: =INDIRECT(ADDRESS(108,AE10,1,1,"Документы АСУТП")) -> #VALUE! | AH10: =INDIRECT(ADDRESS(109,AE10,1,1,"Документы АСУТП")) -> #VALUE! | AI10: =INDIRECT(ADDRESS(110,$AE10,1,1,"Документы АСУТП")) -> #VALUE! | AJ10: =INDIRECT(ADDRESS(111,$AE10,1,1,"Документы АСУТП")) -> #VALUE! | AK10: =INDIRECT(ADDRESS(112,$AE10,1,1,"Документы АСУТП")) -> #VALUE! | AL10: =INDIRECT(ADDRESS(113,$AE10,1,1,"Документы АСУТП")) -> #VALUE! | AM10: =INDIRECT(ADDRESS(114,$AE10,1,1,"Документы АСУТП")) -> #VALUE! | AN10: =INDIRECT(ADDRESS(115,$AE10,1,1,"Документы АСУТП")) -> #VALUE! | AO10: =INDIRECT(ADDRESS(116,$AE10,1,1,"Документы АСУТП")) -> #VALUE! | AP10: =INDIRECT(ADDRESS(117,$AE10,1,1,"Документы АСУТП")) -> #VALUE! | AQ10: =INDIRECT(ADDRESS(118,$AE10,1,1,"Документы АСУТП")) -> #VALUE!
A11: TRUE | B11: =IF(A11, "АВЗ","") -> АВЗ | C11: Kaspersky Security для виртуальных и облачных сред | D11: =IF(A11,INDIRECT(ADDRESS(2,MATCH(C11,'АВЗ АСУТП'!1:1),1,1,"АВЗ АСУТП")),"") -> АВЗ Кол-во серверов управления | E11: 2 | F11: =IF(A11,INDIRECT(ADDRESS(2,MATCH(C11,'АВЗ АСУТП'!1:1)+1,1,1,"АВЗ АСУТП")),"") -> АВЗ Кол-во смежных систем для интеграции | G11: 1 | H11: =IF(A11,INDIRECT(ADDRESS(2,MATCH(C11,'АВЗ АСУТП'!1:1)+2,1,1,"АВЗ АСУТП")),"") -> АВЗ Проектируется только АВЗ (нет=0; да=1) | J11: =IF(AND(A11=TRUE,'Тип разраб-ой док-ции'!$J$4=1),ROUNDUP(IF($F$5 =1,AF2,IF($F$5=2,AG2,IF($F$5 =3,AH2,"-")))/8,2),"-") -> #REF! | K11: =IF(AND(A11=TRUE,'Тип разраб-ой док-ции'!$J$3=1),ROUNDUP(IF($F$5 =1,AI2,IF($F$5=2,AJ2,IF($F$5 =3,AK2,"-")))/8,2),"-") -> #REF! | L11: =IF(AND(A11=TRUE,'Тип разраб-ой док-ции'!$J$2=1),ROUNDUP(IF($F$5 =1,AL2,IF($F$5=2,AM2,IF($F$5 =3,AN2,"-")))/8,2),"-") -> #REF! | M11: =IF(AND(A11=TRUE,'Тип разраб-ой док-ции'!$J$5=1),ROUNDUP(IF($F$5 =1,AO2,IF($F$5=2,AP2,IF($F$5 =3,AQ2,"-")))/8,2),"-") -> #REF! | N11: =SUM('Итоговый расчет АСУТП'!CO4:CO41) -> 17.5 | O11: ='АВЗ АСУТП'!$D$2 -> АВЗ Кол-во серверов управления | P11: =E11 -> 2 | S11: ТЗ | AA11: 0 | AE11: =IF(A18,MATCH(C18,'Документы АСУТП'!$E$3:$CU$3,0),"") + 4 -> #VALUE! | AF11: =INDIRECT(ADDRESS(107,AE11,1,1,"Документы АСУТП")) -> #VALUE! | AG11: =INDIRECT(ADDRESS(108,AE11,1,1,"Документы АСУТП")) -> #VALUE! | AH11: =INDIRECT(ADDRESS(109,AE11,1,1,"Документы АСУТП")) -> #VALUE! | AI11: =INDIRECT(ADDRESS(110,$AE11,1,1,"Документы АСУТП")) -> #VALUE! | AJ11: =INDIRECT(ADDRESS(111,$AE11,1,1,"Документы АСУТП")) -> #VALUE! | AK11: =INDIRECT(ADDRESS(112,$AE11,1,1,"Документы АСУТП")) -> #VALUE! | AL11: =INDIRECT(ADDRESS(113,$AE11,1,1,"Документы АСУТП")) -> #VALUE! | AM11: =INDIRECT(ADDRESS(114,$AE11,1,1,"Документы АСУТП")) -> #VALUE! | AN11: =INDIRECT(ADDRESS(115,$AE11,1,1,"Документы АСУТП")) -> #VALUE! | AO11: =INDIRECT(ADDRESS(116,$AE11,1,1,"Документы АСУТП")) -> #VALUE! | AP11: =INDIRECT(ADDRESS(117,$AE11,1,1,"Документы АСУТП")) -> #VALUE! | AQ11: =INDIRECT(ADDRESS(118,$AE11,1,1,"Документы АСУТП")) -> #VALUE!
A12: TRUE | B12: =IF(A12, "SIEM","") -> SIEM | C12: Kaspersky Unified Monitoring and Analysis Platform (KUMA) | D12: =IF(A12,INDIRECT(ADDRESS(2,MATCH(C12,'SIEM АСУТП'!1:1),1,1,"SIEM АСУТП")),"") -> SIEM Кол-во площадок с компонентами подсистемы | E12: 1 | F12: =IF(A12,INDIRECT(ADDRESS(2,MATCH(C12,'SIEM АСУТП'!1:1)+1,1,1,"SIEM АСУТП")),"") -> SIEM Кол-во типов источников | G12: 1 | H12: =IF(A12,INDIRECT(ADDRESS(2,MATCH(C12,'SIEM АСУТП'!1:1)+2,1,1,"SIEM АСУТП")),"") -> SIEM Проектируется только SIEM (нет=0; да=1) | J12: =IF(AND(A12=TRUE,'Тип разраб-ой док-ции'!$J$4=1),ROUNDUP(IF($F$5 =1,AF5,IF($F$5=2,AG5,IF($F$5 =3,AH5,"-")))/8,2),"-") -> #REF! | K12: =IF(AND(A12=TRUE,'Тип разраб-ой док-ции'!$J$3=1),ROUNDUP(IF($F$5 =1,AI5,IF($F$5=2,AJ5,IF($F$5 =3,AK5,"-")))/8,2),"-") -> #REF! | L12: =IF(AND(A12=TRUE,'Тип разраб-ой док-ции'!$J$2=1),ROUNDUP(IF($F$5 =1,AL5,IF($F$5=2,AM5,IF($F$5 =3,AN5,"-")))/8,2),"-") -> #REF! | M12: =IF(AND(A12=TRUE,'Тип разраб-ой док-ции'!$J$5=1),ROUNDUP(IF($F$5 =1,AO5,IF($F$5=2,AP5,IF($F$5 =3,AQ5,"-")))/8,2),"-") -> #REF! | N12: =SUM('Итоговый расчет АСУТП'!CQ4:CQ41) -> 25.5 | O12: ='АВЗ АСУТП'!$E$2 -> АВЗ Кол-во смежных систем для интеграции | P12: =G11 -> 1 | R12: - | S12: ТЗ | T12: =ROUNDUP('Итоговый расчет АСУТП'!EZ5/8,2) -> 0 | AA12: 0 | AE12: =IF(A20,MATCH(C20,'Документы АСУТП'!$E$3:$CU$3,0),"") + 4 -> #VALUE! | AF12: =INDIRECT(ADDRESS(107,AE12,1,1,"Документы АСУТП")) -> #VALUE! | AG12: =INDIRECT(ADDRESS(108,AE12,1,1,"Документы АСУТП")) -> #VALUE! | AH12: =INDIRECT(ADDRESS(109,AE12,1,1,"Документы АСУТП")) -> #VALUE! | AI12: =INDIRECT(ADDRESS(110,$AE12,1,1,"Документы АСУТП")) -> #VALUE! | AJ12: =INDIRECT(ADDRESS(111,$AE12,1,1,"Документы АСУТП")) -> #VALUE! | AK12: =INDIRECT(ADDRESS(112,$AE12,1,1,"Документы АСУТП")) -> #VALUE! | AL12: =INDIRECT(ADDRESS(113,$AE12,1,1,"Документы АСУТП")) -> #VALUE! | AM12: =INDIRECT(ADDRESS(114,$AE12,1,1,"Документы АСУТП")) -> #VALUE! | AN12: =INDIRECT(ADDRESS(115,$AE12,1,1,"Документы АСУТП")) -> #VALUE! | AO12: =INDIRECT(ADDRESS(116,$AE12,1,1,"Документы АСУТП")) -> #VALUE! | AP12: =INDIRECT(ADDRESS(117,$AE12,1,1,"Документы АСУТП")) -> #VALUE! | AQ12: =INDIRECT(ADDRESS(118,$AE12,1,1,"Документы АСУТП")) -> #VALUE!
A13: FALSE | B13: =IF(A13, "МСЭ","") | D13: =IF(A13,INDIRECT(ADDRESS(2,MATCH(C13,'МСЭ АСУТП'!1:1),1,1,"МСЭ АСУТП")),"") | F13: =IF(A13,INDIRECT(ADDRESS(2,MATCH(C13,'МСЭ АСУТП'!1:1)+1,1,1,"МСЭ АСУТП")),"") | H13: =IF(A13,INDIRECT(ADDRESS(2,MATCH(C13,'МСЭ АСУТП'!1:1)+2,1,1,"МСЭ АСУТП")),"") | J13: =IF(AND(A13=TRUE,'Тип разраб-ой док-ции'!$J$4=1),ROUNDUP(IF($F$5 =1,AF6,IF($F$5=2,AG6,IF($F$5 =3,AH6,"-")))/8,2),"-") -> #REF! | K13: =IF(AND(A13=TRUE,'Тип разраб-ой док-ции'!$J$3=1),ROUNDUP(IF($F$5 =1,AI6,IF($F$5=2,AJ6,IF($F$5 =3,AK6,"-")))/8,2),"-") -> #REF! | L13: =IF(AND(A13=TRUE,'Тип разраб-ой док-ции'!$J$2=1),ROUNDUP(IF($F$5 =1,AL6,IF($F$5=2,AM6,IF($F$5 =3,AN6,"-")))/8,2),"-") -> #REF! | M13: =IF(AND(A13=TRUE,'Тип разраб-ой док-ции'!$J$5=1),ROUNDUP(IF($F$5 =1,AO6,IF($F$5=2,AP6,IF($F$5 =3,AQ6,"-")))/8,2),"-") -> #REF! | N13: =SUM('Итоговый расчет АСУТП'!CS4:CS41) -> 0 | O13: ='АВЗ АСУТП'!$F$2 -> АВЗ Проектируется только АВЗ (нет=0; да=1) | P13: =I11 -> 0 | R13: 0 | S13: ФТТ | T13: =ROUNDUP('Итоговый расчет АСУТП'!EZ6/8,2) -> 0 | V13: 2 | W13: 1 | AA13: 1 | AE13: =IF(A21,MATCH(C21,'Документы АСУТП'!$E$3:$CU$3,0),"") + 4 -> #VALUE! | AF13: =INDIRECT(ADDRESS(107,AE13,1,1,"Документы АСУТП")) -> #VALUE! | AG13: =INDIRECT(ADDRESS(108,AE13,1,1,"Документы АСУТП")) -> #VALUE! | AH13: =INDIRECT(ADDRESS(109,AE13,1,1,"Документы АСУТП")) -> #VALUE! | AI13: =INDIRECT(ADDRESS(110,$AE13,1,1,"Документы АСУТП")) -> #VALUE! | AJ13: =INDIRECT(ADDRESS(111,$AE13,1,1,"Документы АСУТП")) -> #VALUE! | AK13: =INDIRECT(ADDRESS(112,$AE13,1,1,"Документы АСУТП")) -> #VALUE! | AL13: =INDIRECT(ADDRESS(113,$AE13,1,1,"Документы АСУТП")) -> #VALUE! | AM13: =INDIRECT(ADDRESS(114,$AE13,1,1,"Документы АСУТП")) -> #VALUE! | AN13: =INDIRECT(ADDRESS(115,$AE13,1,1,"Документы АСУТП")) -> #VALUE! | AO13: =INDIRECT(ADDRESS(116,$AE13,1,1,"Документы АСУТП")) -> #VALUE! | AP13: =INDIRECT(ADDRESS(117,$AE13,1,1,"Документы АСУТП")) -> #VALUE! | AQ13: =INDIRECT(ADDRESS(118,$AE13,1,1,"Документы АСУТП")) -> #VALUE!
A14: FALSE | B14: =IF(A14, "PIM / PAM / PUM ","") | D14: =IF(A14,INDIRECT(ADDRESS(2,MATCH(C14,'PAM АСУТП'!1:1),1,1,"PAM АСУТП")),"") | F14: =IF(A14,INDIRECT(ADDRESS(2,MATCH(C14,'PAM АСУТП'!1:1)+1,1,1,"PAM АСУТП")),"") | H14: =IF(A14,INDIRECT(ADDRESS(2,MATCH(C14,'PAM АСУТП'!1:1)+2,1,1,"PAM АСУТП")),"") | J14: =IF(AND(A14=TRUE,'Тип разраб-ой док-ции'!$J$4=1),ROUNDUP(IF($F$5 =1,AF7,IF($F$5=2,AG7,IF($F$5 =3,AH7,"-")))/8,2),"-") -> #REF! | K14: =IF(AND(A14=TRUE,'Тип разраб-ой док-ции'!$J$3=1),ROUNDUP(IF($F$5 =1,AI7,IF($F$5=2,AJ7,IF($F$5 =3,AK7,"-")))/8,2),"-") -> #REF! | L14: =IF(AND(A14=TRUE,'Тип разраб-ой док-ции'!$J$2=1),ROUNDUP(IF($F$5 =1,AL7,IF($F$5=2,AM7,IF($F$5 =3,AN7,"-")))/8,2),"-") -> #REF! | M14: =IF(AND(A14=TRUE,'Тип разраб-ой док-ции'!$J$5=1),ROUNDUP(IF($F$5 =1,AO7,IF($F$5=2,AP7,IF($F$5 =3,AQ7,"-")))/8,2),"-") -> #REF! | N14: =SUM('Итоговый расчет АСУТП'!CU4:CU41) -> 0 | O14: ='SIEM АСУТП'!$D$2 -> SIEM Кол-во площадок с компонентами подсистемы | P14: =E12 -> 1 | S14: ЭП | AA14: 1 | AE14: =IF(A22,MATCH(C22,'Документы АСУТП'!$E$3:$CU$3,0),"") + 4 -> #VALUE! | AF14: =INDIRECT(ADDRESS(107,AE14,1,1,"Документы АСУТП")) -> #VALUE! | AG14: =INDIRECT(ADDRESS(108,AE14,1,1,"Документы АСУТП")) -> #VALUE! | AH14: =INDIRECT(ADDRESS(109,AE14,1,1,"Документы АСУТП")) -> #VALUE! | AI14: =INDIRECT(ADDRESS(110,$AE14,1,1,"Документы АСУТП")) -> #VALUE! | AJ14: =INDIRECT(ADDRESS(111,$AE14,1,1,"Документы АСУТП")) -> #VALUE! | AK14: =INDIRECT(ADDRESS(112,$AE14,1,1,"Документы АСУТП")) -> #VALUE! | AL14: =INDIRECT(ADDRESS(113,$AE14,1,1,"Документы АСУТП")) -> #VALUE! | AM14: =INDIRECT(ADDRESS(114,$AE14,1,1,"Документы АСУТП")) -> #VALUE! | AN14: =INDIRECT(ADDRESS(115,$AE14,1,1,"Документы АСУТП")) -> #VALUE! | AO14: =INDIRECT(ADDRESS(116,$AE14,1,1,"Документы АСУТП")) -> #VALUE! | AP14: =INDIRECT(ADDRESS(117,$AE14,1,1,"Документы АСУТП")) -> #VALUE! | AQ14: =INDIRECT(ADDRESS(118,$AE14,1,1,"Документы АСУТП")) -> #VALUE! | AR14: Оставить
A15: FALSE | B15: =IF(A15, "СКЗИ","") | D15: =IF(A15,INDIRECT(ADDRESS(2,MATCH(C15,'СКЗИ АСУТП'!1:1,0),1,1,"СКЗИ АСУТП")),"") | F15: =IF(A15,INDIRECT(ADDRESS(2,MATCH(C15,'СКЗИ АСУТП'!1:1,0)+1,1,1,"СКЗИ АСУТП")),"") | H15: =IF(A15,INDIRECT(ADDRESS(2,MATCH(C15,'СКЗИ АСУТП'!1:1,0)+2,1,1,"СКЗИ АСУТП")),"") | J15: =IF(AND(A15=TRUE,'Тип разраб-ой док-ции'!$J$4=1),ROUNDUP(IF($F$5 =1,AF8,IF($F$5=2,AG8,IF($F$5 =3,AH8,"-")))/8,2),"-") -> #REF! | K15: =IF(AND(A15=TRUE,'Тип разраб-ой док-ции'!$J$3=1),ROUNDUP(IF($F$5 =1,AI8,IF($F$5=2,AJ8,IF($F$5 =3,AK8,"-")))/8,2),"-") -> #REF! | L15: =IF(AND(A15=TRUE,'Тип разраб-ой док-ции'!$J$2=1),ROUNDUP(IF($F$5 =1,AL8,IF($F$5=2,AM8,IF($F$5 =3,AN8,"-")))/8,2),"-") -> #REF! | M15: =IF(AND(A15=TRUE,'Тип разраб-ой док-ции'!$J$5=1),ROUNDUP(IF($F$5 =1,AO8,IF($F$5=2,AP8,IF($F$5 =3,AQ8,"-")))/8,2),"-") -> #REF! | N15: =SUM('Итоговый расчет АСУТП'!CW4:CW41) -> 0 | O15: ='SIEM АСУТП'!$E$2 -> SIEM Кол-во типов источников | P15: =G12 -> 1 | R15: 0 | S15: Пояснительная записка к эскизному проекту | T15: =ROUNDUP('Итоговый расчет АСУТП'!EZ8/8,2) -> 0 | AA15: 0 | AE15: =IF(A23,MATCH(C23,'Документы АСУТП'!$E$3:$CU$3,0),"") + 4 -> #VALUE! | AF15: =INDIRECT(ADDRESS(107,AE15,1,1,"Документы АСУТП")) -> #VALUE! | AG15: =INDIRECT(ADDRESS(108,AE15,1,1,"Документы АСУТП")) -> #VALUE! | AH15: =INDIRECT(ADDRESS(109,AE15,1,1,"Документы АСУТП")) -> #VALUE! | AI15: =INDIRECT(ADDRESS(110,$AE15,1,1,"Документы АСУТП")) -> #VALUE! | AJ15: =INDIRECT(ADDRESS(111,$AE15,1,1,"Документы АСУТП")) -> #VALUE! | AK15: =INDIRECT(ADDRESS(112,$AE15,1,1,"Документы АСУТП")) -> #VALUE! | AL15: =INDIRECT(ADDRESS(113,$AE15,1,1,"Документы АСУТП")) -> #VALUE! | AM15: =INDIRECT(ADDRESS(114,$AE15,1,1,"Документы АСУТП")) -> #VALUE! | AN15: =INDIRECT(ADDRESS(115,$AE15,1,1,"Документы АСУТП")) -> #VALUE! | AO15: =INDIRECT(ADDRESS(116,$AE15,1,1,"Документы АСУТП")) -> #VALUE! | AP15: =INDIRECT(ADDRESS(117,$AE15,1,1,"Документы АСУТП")) -> #VALUE! | AQ15: =INDIRECT(ADDRESS(118,$AE15,1,1,"Документы АСУТП")) -> #VALUE!
A16: FALSE | B16: =IF(A16, "АЗ","") | D16: =IF(A16,INDIRECT(ADDRESS(2,MATCH(C16,'АЗ АСУТП'!1:1,0),1,1,"АЗ АСУТП")),"") | F16: =IF(A16,INDIRECT(ADDRESS(2,MATCH(C16,'АЗ АСУТП'!1:1,0)+1,1,1,"АЗ АСУТП")),"") | H16: =IF(A16,INDIRECT(ADDRESS(2,MATCH(C16,'АЗ АСУТП'!1:1,0)+2,1,1,"АЗ АСУТП")),"") | J16: =IF(AND(A16=TRUE,'Тип разраб-ой док-ции'!$J$4=1),ROUNDUP(IF($F$5 =1,AF9,IF($F$5=2,AG9,IF($F$5 =3,AH9,"-")))/8,2),"-") -> #REF! | K16: =IF(AND(A16=TRUE,'Тип разраб-ой док-ции'!$J$3=1),ROUNDUP(IF($F$5 =1,AI9,IF($F$5=2,AJ9,IF($F$5 =3,AK9,"-")))/8,2),"-") -> #REF! | L16: =IF(AND(A16=TRUE,'Тип разраб-ой док-ции'!$J$2=1),ROUNDUP(IF($F$5 =1,AL9,IF($F$5=2,AM9,IF($F$5 =3,AN9,"-")))/8,2),"-") -> #REF! | M16: =IF(AND(A16=TRUE,'Тип разраб-ой док-ции'!$J$5=1),ROUNDUP(IF($F$5 =1,AO9,IF($F$5=2,AP9,IF($F$5 =3,AQ9,"-")))/8,2),"-") -> #REF! | N16: =SUM('Итоговый расчет АСУТП'!CY4:CY41) -> 0 | O16: ='SIEM АСУТП'!$F$2 -> SIEM Проектируется только SIEM (нет=0; да=1) | P16: =I12 -> 0 | S16: ТП | AA16: 0 | AE16: =IF(A24,MATCH(C24,'Документы АСУТП'!$E$3:$CU$3,0),"") + 4 -> #VALUE! | AF16: =INDIRECT(ADDRESS(107,AE16,1,1,"Документы АСУТП")) -> #VALUE! | AG16: =INDIRECT(ADDRESS(108,AE16,1,1,"Документы АСУТП")) -> #VALUE! | AH16: =INDIRECT(ADDRESS(109,AE16,1,1,"Документы АСУТП")) -> #VALUE! | AI16: =INDIRECT(ADDRESS(110,$AE16,1,1,"Документы АСУТП")) -> #VALUE! | AJ16: =INDIRECT(ADDRESS(111,$AE16,1,1,"Документы АСУТП")) -> #VALUE! | AK16: =INDIRECT(ADDRESS(112,$AE16,1,1,"Документы АСУТП")) -> #VALUE! | AL16: =INDIRECT(ADDRESS(113,$AE16,1,1,"Документы АСУТП")) -> #VALUE! | AM16: =INDIRECT(ADDRESS(114,$AE16,1,1,"Документы АСУТП")) -> #VALUE! | AN16: =INDIRECT(ADDRESS(115,$AE16,1,1,"Документы АСУТП")) -> #VALUE! | AO16: =INDIRECT(ADDRESS(116,$AE16,1,1,"Документы АСУТП")) -> #VALUE! | AP16: =INDIRECT(ADDRESS(117,$AE16,1,1,"Документы АСУТП")) -> #VALUE! | AQ16: =INDIRECT(ADDRESS(118,$AE16,1,1,"Документы АСУТП")) -> #VALUE!
A17: FALSE | B17: =IF(A17, "СРК","") | D17: =IF(A17,INDIRECT(ADDRESS(2,MATCH(C17,'РК АСУТП'!1:1),1,1,"РК АСУТП")),"") | F17: =IF(A17,INDIRECT(ADDRESS(2,MATCH(C17,'РК АСУТП'!1:1)+1,1,1,"РК АСУТП")),"") | H17: =IF(A17,INDIRECT(ADDRESS(2,MATCH(C17,'РК АСУТП'!1:1)+2,1,1,"РК АСУТП")),"") | J17: =IF(AND(A17=TRUE,'Тип разраб-ой док-ции'!$J$4=1),ROUNDUP(IF($F$5 =1,AF10,IF($F$5=2,AG10,IF($F$5 =3,AH10,"-")))/8,2),"-") -> #REF! | K17: =IF(AND(A17=TRUE,'Тип разраб-ой док-ции'!$J$3=1),ROUNDUP(IF($F$5 =1,AI10,IF($F$5=2,AJ10,IF($F$5 =3,AK10,"-")))/8,2),"-") -> #REF! | L17: =IF(AND(A17=TRUE,'Тип разраб-ой док-ции'!$J$2=1),ROUNDUP(IF($F$5 =1,AL10,IF($F$5=2,AM10,IF($F$5 =3,AN10,"-")))/8,2),"-") -> #REF! | M17: =IF(AND(A17=TRUE,'Тип разраб-ой док-ции'!$J$5=1),ROUNDUP(IF($F$5 =1,AO10,IF($F$5=2,AP10,IF($F$5 =3,AQ10,"-")))/8,2),"-") -> #REF! | N17: =SUM('Итоговый расчет АСУТП'!DA4:DA41) -> 0 | O17: ='МСЭ АСУТП'!$D$2 -> МЭ Кол-во площадок | P17: =E13 -> 0 | R17: 1 | S17: Ведомость технического проекта | T17: =ROUNDUP('Итоговый расчет АСУТП'!EZ10/8,2) -> #REF! | AA17: 1 | AE17: =IF(A25,MATCH(C25,'Документы АСУТП'!$E$3:$CU$3,0),"") + 4 -> #VALUE! | AF17: =INDIRECT(ADDRESS(107,AE17,1,1,"Документы АСУТП")) -> #VALUE! | AG17: =INDIRECT(ADDRESS(108,AE17,1,1,"Документы АСУТП")) -> #VALUE! | AH17: =INDIRECT(ADDRESS(109,AE17,1,1,"Документы АСУТП")) -> #VALUE! | AI17: =INDIRECT(ADDRESS(110,$AE17,1,1,"Документы АСУТП")) -> #VALUE! | AJ17: =INDIRECT(ADDRESS(111,$AE17,1,1,"Документы АСУТП")) -> #VALUE! | AK17: =INDIRECT(ADDRESS(112,$AE17,1,1,"Документы АСУТП")) -> #VALUE! | AL17: =INDIRECT(ADDRESS(113,$AE17,1,1,"Документы АСУТП")) -> #VALUE! | AM17: =INDIRECT(ADDRESS(114,$AE17,1,1,"Документы АСУТП")) -> #VALUE! | AN17: =INDIRECT(ADDRESS(115,$AE17,1,1,"Документы АСУТП")) -> #VALUE! | AO17: =INDIRECT(ADDRESS(116,$AE17,1,1,"Документы АСУТП")) -> #VALUE! | AP17: =INDIRECT(ADDRESS(117,$AE17,1,1,"Документы АСУТП")) -> #VALUE! | AQ17: =INDIRECT(ADDRESS(118,$AE17,1,1,"Документы АСУТП")) -> #VALUE!
A18: FALSE | B18: =IF(A18, "Обнаружение вторжений (IDS/IPS)","") | D18: =IF(A18,INDIRECT(ADDRESS(2,MATCH(C18,'IDS АСУТП'!1:1),1,1,"IDS АСУТП")),"") | F18: =IF(A18,INDIRECT(ADDRESS(2,MATCH(C18,'IDS АСУТП'!1:1)+1,1,1,"IDS АСУТП")),"") | H18: =IF(A18,INDIRECT(ADDRESS(2,MATCH(C18,'IDS АСУТП'!1:1)+2,1,1,"IDS АСУТП")),"") | J18: =IF(AND(A18=TRUE,'Тип разраб-ой док-ции'!$J$4=1),ROUNDUP(IF($F$5 =1,AF11,IF($F$5=2,AG11,IF($F$5 =3,AH11,"-")))/8,2),"-") -> #REF! | K18: =IF(AND(A18=TRUE,'Тип разраб-ой док-ции'!$J$3=1),ROUNDUP(IF($F$5 =1,AI11,IF($F$5=2,AJ11,IF($F$5 =3,AK11,"-")))/8,2),"-") -> #REF! | L18: =IF(AND(A18=TRUE,'Тип разраб-ой док-ции'!$J$2=1),ROUNDUP(IF($F$5 =1,AL11,IF($F$5=2,AM11,IF($F$5 =3,AN11,"-")))/8,2),"-") -> #REF! | M18: =IF(AND(A18=TRUE,'Тип разраб-ой док-ции'!$J$5=1),ROUNDUP(IF($F$5 =1,AO11,IF($F$5=2,AP11,IF($F$5 =3,AQ11,"-")))/8,2),"-") -> #REF! | N18: =SUM('Итоговый расчет АСУТП'!DC4:DC41) -> 0 | O18: ='МСЭ АСУТП'!$E$2 -> МЭ Кол-во серверов управления | P18: =G13 -> 0 | R18: - | S18: Ведомость покупных изделий | T18: =ROUNDUP('Итоговый расчет АСУТП'!EZ11/8,2) -> 0 | AA18: 1 | AE18: =IF(A26,MATCH(C26,'Документы АСУТП'!$E$3:$CU$3,0),"") + 4 -> #VALUE! | AF18: =INDIRECT(ADDRESS(107,AE18,1,1,"Документы АСУТП")) -> #VALUE! | AG18: =INDIRECT(ADDRESS(108,AE18,1,1,"Документы АСУТП")) -> #VALUE! | AH18: =INDIRECT(ADDRESS(109,AE18,1,1,"Документы АСУТП")) -> #VALUE! | AI18: =INDIRECT(ADDRESS(110,$AE18,1,1,"Документы АСУТП")) -> #VALUE! | AJ18: =INDIRECT(ADDRESS(111,$AE18,1,1,"Документы АСУТП")) -> #VALUE! | AK18: =INDIRECT(ADDRESS(112,$AE18,1,1,"Документы АСУТП")) -> #VALUE! | AL18: =INDIRECT(ADDRESS(113,$AE18,1,1,"Документы АСУТП")) -> #VALUE! | AM18: =INDIRECT(ADDRESS(114,$AE18,1,1,"Документы АСУТП")) -> #VALUE! | AN18: =INDIRECT(ADDRESS(115,$AE18,1,1,"Документы АСУТП")) -> #VALUE! | AO18: =INDIRECT(ADDRESS(116,$AE18,1,1,"Документы АСУТП")) -> #VALUE! | AP18: =INDIRECT(ADDRESS(117,$AE18,1,1,"Документы АСУТП")) -> #VALUE! | AQ18: =INDIRECT(ADDRESS(118,$AE18,1,1,"Документы АСУТП")) -> #VALUE!
A19: FALSE | B19: =IF(A19, "НСД","") | D19: =IF(A19,INDIRECT(ADDRESS(2,MATCH(C19,'НСД АСУТП'!1:1),1,1,"НСД АСУТП")),"") | F19: =IF(A19,INDIRECT(ADDRESS(2,MATCH(C19,'НСД АСУТП'!1:1)+1,1,1,"НСД АСУТП")),"") | H19: =IF(A19,INDIRECT(ADDRESS(2,MATCH(C19,'НСД АСУТП'!1:1)+2,1,1,"НСД АСУТП")),"") | J19: =IF(AND(A19=TRUE,'Тип разраб-ой док-ции'!$J$4=1),ROUNDUP(IF($F$5 =1,AF33,IF($F$5=2,AG33,IF($F$5 =3,AH33,"-")))/8,2),"-") -> #REF! | K19: =IF(AND(A19=TRUE,'Тип разраб-ой док-ции'!$J$3=1),ROUNDUP(IF($F$5 =1,AI33,IF($F$5=2,AJ33,IF($F$5 =3,AK33,"-")))/8,2),"-") -> #REF! | L19: =IF(AND(A19=TRUE,'Тип разраб-ой док-ции'!$J$2=1),ROUNDUP(IF($F$5 =1,AL33,IF($F$5=2,AM33,IF($F$5 =3,AN33,"-")))/8,2),"-") -> #REF! | M19: =IF(AND(A19=TRUE,'Тип разраб-ой док-ции'!$J$5=1),ROUNDUP(IF($F$5 =1,AO33,IF($F$5=2,AP33,IF($F$5 =3,AQ33,"-")))/8,2),"-") -> #REF! | N19: =SUM('Итоговый расчет АСУТП'!DE3:DE40) -> 0 | O19: ='МСЭ АСУТП'!$F$2 -> МЭ Кол-во модулей | P19: =I13 -> 0 | R19: 1 | S19: Пояснительная записка к техническому проекту | T19: =ROUNDUP('Итоговый расчет АСУТП'!EZ12/8,2) -> #REF! | AA19: 0 | AE19: =IF(A27,MATCH(C27,'Документы АСУТП'!$E$3:$CU$3,0),"") + 4 -> #VALUE! | AF19: =INDIRECT(ADDRESS(107,AE19,1,1,"Документы АСУТП")) -> #VALUE! | AG19: =INDIRECT(ADDRESS(108,AE19,1,1,"Документы АСУТП")) -> #VALUE! | AH19: =INDIRECT(ADDRESS(109,AE19,1,1,"Документы АСУТП")) -> #VALUE! | AI19: =INDIRECT(ADDRESS(110,$AE19,1,1,"Документы АСУТП")) -> #VALUE! | AJ19: =INDIRECT(ADDRESS(111,$AE19,1,1,"Документы АСУТП")) -> #VALUE! | AK19: =INDIRECT(ADDRESS(112,$AE19,1,1,"Документы АСУТП")) -> #VALUE! | AL19: =INDIRECT(ADDRESS(113,$AE19,1,1,"Документы АСУТП")) -> #VALUE! | AM19: =INDIRECT(ADDRESS(114,$AE19,1,1,"Документы АСУТП")) -> #VALUE! | AN19: =INDIRECT(ADDRESS(115,$AE19,1,1,"Документы АСУТП")) -> #VALUE! | AO19: =INDIRECT(ADDRESS(116,$AE19,1,1,"Документы АСУТП")) -> #VALUE! | AP19: =INDIRECT(ADDRESS(117,$AE19,1,1,"Документы АСУТП")) -> #VALUE! | AQ19: =INDIRECT(ADDRESS(118,$AE19,1,1,"Документы АСУТП")) -> #VALUE!
A20: FALSE | B20: =IF(A20, "АПДМЗ","") | D20: =IF(A20,INDIRECT(ADDRESS(2,MATCH(C20,'АПМДЗ АСУТП'!1:1),1,1,"АПМДЗ АСУТП")),"") | F20: =IF(A20,INDIRECT(ADDRESS(2,MATCH(C20,'АПМДЗ АСУТП'!1:1)+1,1,1,"АПМДЗ АСУТП")),"") | H20: =IF(A20,INDIRECT(ADDRESS(2,MATCH(C20,'АПМДЗ АСУТП'!1:1)+2,1,1,"АПМДЗ АСУТП")),"") | J20: =IF(AND(A20=TRUE,'Тип разраб-ой док-ции'!$J$4=1),ROUNDUP(IF($F$5 =1,AF12,IF($F$5=2,AG12,IF($F$5 =3,AH12,"-")))/8,2),"-") -> #REF! | K20: =IF(AND(A20=TRUE,'Тип разраб-ой док-ции'!$J$3=1),ROUNDUP(IF($F$5 =1,AI12,IF($F$5=2,AJ12,IF($F$5 =3,AK12,"-")))/8,2),"-") -> #REF! | L20: =IF(AND(A20=TRUE,'Тип разраб-ой док-ции'!$J$2=1),ROUNDUP(IF($F$5 =1,AL12,IF($F$5=2,AM12,IF($F$5 =3,AN12,"-")))/8,2),"-") -> #REF! | M20: =IF(AND(A20=TRUE,'Тип разраб-ой док-ции'!$J$5=1),ROUNDUP(IF($F$5 =1,AO12,IF($F$5=2,AP12,IF($F$5 =3,AQ12,"-")))/8,2),"-") -> #REF! | N20: =SUM('Итоговый расчет АСУТП'!DG3:DG40) -> 0 | O20: ='PAM АСУТП'!$D$2 -> PAM Кол-во инсталляций | P20: =E14 -> 0 | R20: 1 | S20: Описание комплекса технических средств | T20: =ROUNDUP('Итоговый расчет АСУТП'!EZ13/8,2) -> #REF! | AA20: 1 | AE20: =IF(A28,MATCH(C28,'Документы АСУТП'!$E$3:$CU$3,0),"") + 4 -> #VALUE! | AF20: =INDIRECT(ADDRESS(107,AE20,1,1,"Документы АСУТП")) -> #VALUE! | AG20: =INDIRECT(ADDRESS(108,AE20,1,1,"Документы АСУТП")) -> #VALUE! | AH20: =INDIRECT(ADDRESS(109,AE20,1,1,"Документы АСУТП")) -> #VALUE! | AI20: =INDIRECT(ADDRESS(110,$AE20,1,1,"Документы АСУТП")) -> #VALUE! | AJ20: =INDIRECT(ADDRESS(111,$AE20,1,1,"Документы АСУТП")) -> #VALUE! | AK20: =INDIRECT(ADDRESS(112,$AE20,1,1,"Документы АСУТП")) -> #VALUE! | AL20: =INDIRECT(ADDRESS(113,$AE20,1,1,"Документы АСУТП")) -> #VALUE! | AM20: =INDIRECT(ADDRESS(114,$AE20,1,1,"Документы АСУТП")) -> #VALUE! | AN20: =INDIRECT(ADDRESS(115,$AE20,1,1,"Документы АСУТП")) -> #VALUE! | AO20: =INDIRECT(ADDRESS(116,$AE20,1,1,"Документы АСУТП")) -> #VALUE! | AP20: =INDIRECT(ADDRESS(117,$AE20,1,1,"Документы АСУТП")) -> #VALUE! | AQ20: =INDIRECT(ADDRESS(118,$AE20,1,1,"Документы АСУТП")) -> #VALUE!
A21: FALSE | B21: =IF(A21, "MFA","") | D21: =IF(A21,INDIRECT(ADDRESS(2,MATCH(C21,'MFA АСУТП'!1:1,0),1,1,"MFA АСУТП")),"") | F21: =IF(A21,INDIRECT(ADDRESS(2,MATCH(C21,'MFA АСУТП'!1:1,0)+1,1,1,"MFA АСУТП")),"") | H21: =IF(A21,INDIRECT(ADDRESS(2,MATCH(C21,'MFA АСУТП'!1:1,0)+2,1,1,"MFA АСУТП")),"") | J21: =IF(AND(A21=TRUE,'Тип разраб-ой док-ции'!$J$4=1),ROUNDUP(IF($F$5 =1,AF13,IF($F$5=2,AG13,IF($F$5 =3,AH13,"-")))/8,2),"-") -> #REF! | K21: =IF(AND(A21=TRUE,'Тип разраб-ой док-ции'!$J$3=1),ROUNDUP(IF($F$5 =1,AI13,IF($F$5=2,AJ13,IF($F$5 =3,AK13,"-")))/8,2),"-") -> #REF! | L21: =IF(AND(A21=TRUE,'Тип разраб-ой док-ции'!$J$2=1),ROUNDUP(IF($F$5 =1,AL13,IF($F$5=2,AM13,IF($F$5 =3,AN13,"-")))/8,2),"-") -> #REF! | M21: =IF(AND(A21=TRUE,'Тип разраб-ой док-ции'!$J$5=1),ROUNDUP(IF($F$5 =1,AO13,IF($F$5=2,AP13,IF($F$5 =3,AQ13,"-")))/8,2),"-") -> #REF! | N21: =SUM('Итоговый расчет АСУТП'!DI4:DI41) -> 0 | O21: ='PAM АСУТП'!$E$2 -> PAM Кол-во типов протоколов подключения | P21: =G14 -> 0 | R21: 1 | S21: Описание программного обеспечения | T21: =ROUNDUP('Итоговый расчет АСУТП'!EZ14/8,2) -> #REF! | AA21: 0 | AE21: =IF(A29,MATCH(C29,'Документы АСУТП'!$E$3:$CU$3,0),"") + 4 -> #VALUE! | AF21: =INDIRECT(ADDRESS(107,AE21,1,1,"Документы АСУТП")) -> #VALUE! | AG21: =INDIRECT(ADDRESS(108,AE21,1,1,"Документы АСУТП")) -> #VALUE! | AH21: =INDIRECT(ADDRESS(109,AE21,1,1,"Документы АСУТП")) -> #VALUE! | AI21: =INDIRECT(ADDRESS(110,$AE21,1,1,"Документы АСУТП")) -> #VALUE! | AJ21: =INDIRECT(ADDRESS(111,$AE21,1,1,"Документы АСУТП")) -> #VALUE! | AK21: =INDIRECT(ADDRESS(112,$AE21,1,1,"Документы АСУТП")) -> #VALUE! | AL21: =INDIRECT(ADDRESS(113,$AE21,1,1,"Документы АСУТП")) -> #VALUE! | AM21: =INDIRECT(ADDRESS(114,$AE21,1,1,"Документы АСУТП")) -> #VALUE! | AN21: =INDIRECT(ADDRESS(115,$AE21,1,1,"Документы АСУТП")) -> #VALUE! | AO21: =INDIRECT(ADDRESS(116,$AE21,1,1,"Документы АСУТП")) -> #VALUE! | AP21: =INDIRECT(ADDRESS(117,$AE21,1,1,"Документы АСУТП")) -> #VALUE! | AQ21: =INDIRECT(ADDRESS(118,$AE21,1,1,"Документы АСУТП")) -> #VALUE!
A22: FALSE | B22: =IF(A22, "ДИОД","") | D22: =IF(A22,INDIRECT(ADDRESS(2,MATCH(C22,'ДИОД АСУТП'!1:1,0),1,1,"ДИОД АСУТП")),"") | F22: =IF(A22,INDIRECT(ADDRESS(2,MATCH(C22,'ДИОД АСУТП'!1:1,0)+1,1,1,"ДИОД АСУТП")),"") | H22: =IF(A22,INDIRECT(ADDRESS(2,MATCH(C22,'ДИОД АСУТП'!1:1,0)+2,1,1,"ДИОД АСУТП")),"") | J22: =IF(AND(A22=TRUE,'Тип разраб-ой док-ции'!$J$4=1),ROUNDUP(IF($F$5 =1,AF14,IF($F$5=2,AG14,IF($F$5 =3,AH14,"-")))/8,2),"-") -> #REF! | K22: =IF(AND(A22=TRUE,'Тип разраб-ой док-ции'!$J$3=1),ROUNDUP(IF($F$5 =1,AI14,IF($F$5=2,AJ14,IF($F$5 =3,AK14,"-")))/8,2),"-") -> #REF! | L22: =IF(AND(A22=TRUE,'Тип разраб-ой док-ции'!$J$2=1),ROUNDUP(IF($F$5 =1,AL14,IF($F$5=2,AM14,IF($F$5 =3,AN14,"-")))/8,2),"-") -> #REF! | M22: =IF(AND(A22=TRUE,'Тип разраб-ой док-ции'!$J$5=1),ROUNDUP(IF($F$5 =1,AO14,IF($F$5=2,AP14,IF($F$5 =3,AQ14,"-")))/8,2),"-") -> #REF! | N22: =SUM('Итоговый расчет АСУТП'!DK4:DK41) -> 0 | O22: ='PAM АСУТП'!$F$2 -> PAM Неиспользуемый параметр | P22: =I14 -> 0 | R22: 1 | S22: Схема структурная | T22: =ROUNDUP('Итоговый расчет АСУТП'!EZ15/8,2) -> #REF! | AA22: 1 | AE22: =IF(A30,MATCH(C30,'Документы АСУТП'!$E$3:$CU$3,0),"") + 4 -> #VALUE! | AF22: =INDIRECT(ADDRESS(107,AE22,1,1,"Документы АСУТП")) -> #VALUE! | AG22: =INDIRECT(ADDRESS(108,AE22,1,1,"Документы АСУТП")) -> #VALUE! | AH22: =INDIRECT(ADDRESS(109,AE22,1,1,"Документы АСУТП")) -> #VALUE! | AI22: =INDIRECT(ADDRESS(110,$AE22,1,1,"Документы АСУТП")) -> #VALUE! | AJ22: =INDIRECT(ADDRESS(111,$AE22,1,1,"Документы АСУТП")) -> #VALUE! | AK22: =INDIRECT(ADDRESS(112,$AE22,1,1,"Документы АСУТП")) -> #VALUE! | AL22: =INDIRECT(ADDRESS(113,$AE22,1,1,"Документы АСУТП")) -> #VALUE! | AM22: =INDIRECT(ADDRESS(114,$AE22,1,1,"Документы АСУТП")) -> #VALUE! | AN22: =INDIRECT(ADDRESS(115,$AE22,1,1,"Документы АСУТП")) -> #VALUE! | AO22: =INDIRECT(ADDRESS(116,$AE22,1,1,"Документы АСУТП")) -> #VALUE! | AP22: =INDIRECT(ADDRESS(117,$AE22,1,1,"Документы АСУТП")) -> #VALUE! | AQ22: =INDIRECT(ADDRESS(118,$AE22,1,1,"Документы АСУТП")) -> #VALUE!
A23: FALSE | B23: =IF(A23, "СЗВ","") | D23: =IF(A23,INDIRECT(ADDRESS(2,MATCH(C23,'СЗВ АСУТП'!1:1),1,1,"СЗВ АСУТП")),"") | F23: =IF(A23,INDIRECT(ADDRESS(2,MATCH(C23,'СЗВ АСУТП'!1:1)+1,1,1,"СЗВ АСУТП")),"") | H23: =IF(A23,INDIRECT(ADDRESS(2,MATCH(C23,'СЗВ АСУТП'!1:1)+2,1,1,"СЗВ АСУТП")),"") | J23: =IF(AND(A23=TRUE,'Тип разраб-ой док-ции'!$J$4=1),ROUNDUP(IF($F$5 =1,AF15,IF($F$5=2,AG15,IF($F$5 =3,AH15,"-")))/8,2),"-") -> #REF! | K23: =IF(AND(A23=TRUE,'Тип разраб-ой док-ции'!$J$3=1),ROUNDUP(IF($F$5 =1,AI15,IF($F$5=2,AJ15,IF($F$5 =3,AK15,"-")))/8,2),"-") -> #REF! | L23: =IF(AND(A23=TRUE,'Тип разраб-ой док-ции'!$J$2=1),ROUNDUP(IF($F$5 =1,AL15,IF($F$5=2,AM15,IF($F$5 =3,AN15,"-")))/8,2),"-") -> #REF! | M23: =IF(AND(A23=TRUE,'Тип разраб-ой док-ции'!$J$5=1),ROUNDUP(IF($F$5 =1,AO15,IF($F$5=2,AP15,IF($F$5 =3,AQ15,"-")))/8,2),"-") -> #REF! | N23: =SUM('Итоговый расчет АСУТП'!DM4:DM41) -> 0 | O23: ='СКЗИ АСУТП'!D$2 -> СКЗИ Количество площадок | P23: =E15 -> 0 | R23: 1 | S23: Схема функциональная | T23: =ROUNDUP('Итоговый расчет АСУТП'!EZ16/8,2) -> #REF! | AA23: 0 | AE23: =IF(A31,MATCH(C31,'Документы АСУТП'!$E$3:$CU$3,0),"") + 4 -> #VALUE! | AF23: =INDIRECT(ADDRESS(107,AE23,1,1,"Документы АСУТП")) -> #VALUE! | AG23: =INDIRECT(ADDRESS(108,AE23,1,1,"Документы АСУТП")) -> #VALUE! | AH23: =INDIRECT(ADDRESS(109,AE23,1,1,"Документы АСУТП")) -> #VALUE! | AI23: =INDIRECT(ADDRESS(110,$AE23,1,1,"Документы АСУТП")) -> #VALUE! | AJ23: =INDIRECT(ADDRESS(111,$AE23,1,1,"Документы АСУТП")) -> #VALUE! | AK23: =INDIRECT(ADDRESS(112,$AE23,1,1,"Документы АСУТП")) -> #VALUE! | AL23: =INDIRECT(ADDRESS(113,$AE23,1,1,"Документы АСУТП")) -> #VALUE! | AM23: =INDIRECT(ADDRESS(114,$AE23,1,1,"Документы АСУТП")) -> #VALUE! | AN23: =INDIRECT(ADDRESS(115,$AE23,1,1,"Документы АСУТП")) -> #VALUE! | AO23: =INDIRECT(ADDRESS(116,$AE23,1,1,"Документы АСУТП")) -> #VALUE! | AP23: =INDIRECT(ADDRESS(117,$AE23,1,1,"Документы АСУТП")) -> #VALUE! | AQ23: =INDIRECT(ADDRESS(118,$AE23,1,1,"Документы АСУТП")) -> #VALUE!
A24: FALSE | B24: =IF(A24, "SOAR/IRP+SGRC","") | D24: =IF(A24,INDIRECT(ADDRESS(2,MATCH(C24,'SOAR АСУТП'!1:1),1,1,"SOAR АСУТП")),"") | F24: =IF(A24,INDIRECT(ADDRESS(2,MATCH(C24,'SOAR АСУТП'!1:1)+1,1,1,"SOAR АСУТП")),"") | H24: =IF(A24,INDIRECT(ADDRESS(2,MATCH(C24,'SOAR АСУТП'!1:1)+2,1,1,"SOAR АСУТП")),"") | J24: =IF(AND(A24=TRUE,'Тип разраб-ой док-ции'!$J$4=1),ROUNDUP(IF($F$5 =1,AF16,IF($F$5=2,AG16,IF($F$5 =3,AH16,"-")))/8,2),"-") -> #REF! | K24: =IF(AND(A24=TRUE,'Тип разраб-ой док-ции'!$J$3=1),ROUNDUP(IF($F$5 =1,AI16,IF($F$5=2,AJ16,IF($F$5 =3,AK16,"-")))/8,2),"-") -> #REF! | L24: =IF(AND(A24=TRUE,'Тип разраб-ой док-ции'!$J$2=1),ROUNDUP(IF($F$5 =1,AL16,IF($F$5=2,AM16,IF($F$5 =3,AN16,"-")))/8,2),"-") -> #REF! | M24: =IF(AND(A24=TRUE,'Тип разраб-ой док-ции'!$J$5=1),ROUNDUP(IF($F$5 =1,AO16,IF($F$5=2,AP16,IF($F$5 =3,AQ16,"-")))/8,2),"-") -> #REF! | N24: =SUM('Итоговый расчет АСУТП'!DO4:DO41) -> #REF! | O24: ='СКЗИ АСУТП'!E$2 -> СКЗИ Кол-во ЦУС | P24: =G15 -> 0 | S24: ТРП (дополнительно к ПЗ нужно выбрать документы из состава РД) | AA24: 0 | AE24: =IF(A32,MATCH(C32,'Документы АСУТП'!$E$3:$CU$3,0),"") + 4 -> #VALUE! | AF24: =INDIRECT(ADDRESS(107,AE24,1,1,"Документы АСУТП")) -> #VALUE! | AG24: =INDIRECT(ADDRESS(108,AE24,1,1,"Документы АСУТП")) -> #VALUE! | AH24: =INDIRECT(ADDRESS(109,AE24,1,1,"Документы АСУТП")) -> #VALUE! | AI24: =INDIRECT(ADDRESS(110,$AE24,1,1,"Документы АСУТП")) -> #VALUE! | AJ24: =INDIRECT(ADDRESS(111,$AE24,1,1,"Документы АСУТП")) -> #VALUE! | AK24: =INDIRECT(ADDRESS(112,$AE24,1,1,"Документы АСУТП")) -> #VALUE! | AL24: =INDIRECT(ADDRESS(113,$AE24,1,1,"Документы АСУТП")) -> #VALUE! | AM24: =INDIRECT(ADDRESS(114,$AE24,1,1,"Документы АСУТП")) -> #VALUE! | AN24: =INDIRECT(ADDRESS(115,$AE24,1,1,"Документы АСУТП")) -> #VALUE! | AO24: =INDIRECT(ADDRESS(116,$AE24,1,1,"Документы АСУТП")) -> #VALUE! | AP24: =INDIRECT(ADDRESS(117,$AE24,1,1,"Документы АСУТП")) -> #VALUE! | AQ24: =INDIRECT(ADDRESS(118,$AE24,1,1,"Документы АСУТП")) -> #VALUE!
A25: FALSE | B25: =IF(A25, "Виртуализация рабочих мест (VDI)","") | D25: =IF(A25,INDIRECT(ADDRESS(2,MATCH(C25,'VDI АСУТП'!1:1,0),1,1,"VDI АСУТП")),"") | F25: =IF(A25,INDIRECT(ADDRESS(2,MATCH(C25,'VDI АСУТП'!1:1,0)+1,1,1,"VDI АСУТП")),"") | H25: =IF(A25,INDIRECT(ADDRESS(2,MATCH(C25,'VDI АСУТП'!1:1,0)+2,1,1,"VDI АСУТП")),"") | J25: =IF(AND(A25=TRUE,'Тип разраб-ой док-ции'!$J$4=1),ROUNDUP(IF($F$5 =1,AF17,IF($F$5=2,AG17,IF($F$5 =3,AH17,"-")))/8,2),"-") -> #REF! | K25: =IF(AND(A25=TRUE,'Тип разраб-ой док-ции'!$J$3=1),ROUNDUP(IF($F$5 =1,AI17,IF($F$5=2,AJ17,IF($F$5 =3,AK17,"-")))/8,2),"-") -> #REF! | L25: =IF(AND(A25=TRUE,'Тип разраб-ой док-ции'!$J$2=1),ROUNDUP(IF($F$5 =1,AL17,IF($F$5=2,AM17,IF($F$5 =3,AN17,"-")))/8,2),"-") -> #REF! | M25: =IF(AND(A25=TRUE,'Тип разраб-ой док-ции'!$J$5=1),ROUNDUP(IF($F$5 =1,AO17,IF($F$5=2,AP17,IF($F$5 =3,AQ17,"-")))/8,2),"-") -> #REF! | N25: =SUM('Итоговый расчет АСУТП'!DQ4:DQ41) -> 0 | O25: ='СКЗИ АСУТП'!F$2 -> СКЗИ Количество пользователей | P25: =I15 -> 0 | R25: - | S25: Пояснительная записка к техническому проекту | T25: =ROUNDUP('Итоговый расчет АСУТП'!EZ18/8,2) -> 0 | AA25: 1 | AE25: =IF(A33,MATCH(C33,'Документы АСУТП'!$E$3:$CU$3,0),"") + 4 -> #VALUE! | AF25: =INDIRECT(ADDRESS(107,AE25,1,1,"Документы АСУТП")) -> #VALUE! | AG25: =INDIRECT(ADDRESS(108,AE25,1,1,"Документы АСУТП")) -> #VALUE! | AH25: =INDIRECT(ADDRESS(109,AE25,1,1,"Документы АСУТП")) -> #VALUE! | AI25: =INDIRECT(ADDRESS(110,$AE25,1,1,"Документы АСУТП")) -> #VALUE! | AJ25: =INDIRECT(ADDRESS(111,$AE25,1,1,"Документы АСУТП")) -> #VALUE! | AK25: =INDIRECT(ADDRESS(112,$AE25,1,1,"Документы АСУТП")) -> #VALUE! | AL25: =INDIRECT(ADDRESS(113,$AE25,1,1,"Документы АСУТП")) -> #VALUE! | AM25: =INDIRECT(ADDRESS(114,$AE25,1,1,"Документы АСУТП")) -> #VALUE! | AN25: =INDIRECT(ADDRESS(115,$AE25,1,1,"Документы АСУТП")) -> #VALUE! | AO25: =INDIRECT(ADDRESS(116,$AE25,1,1,"Документы АСУТП")) -> #VALUE! | AP25: =INDIRECT(ADDRESS(117,$AE25,1,1,"Документы АСУТП")) -> #VALUE! | AQ25: =INDIRECT(ADDRESS(118,$AE25,1,1,"Документы АСУТП")) -> #VALUE!
A26: FALSE | B26: =IF(A26, "СУБД","") | D26: =IF(A26,INDIRECT(ADDRESS(2,MATCH(C26,'СУБД АСУТП'!1:1,0),1,1,"СУБД АСУТП")),"") | F26: =IF(A26,INDIRECT(ADDRESS(2,MATCH(C26,'СУБД АСУТП'!1:1,0)+1,1,1,"СУБД АСУТП")),"") | H26: =IF(A26,INDIRECT(ADDRESS(2,MATCH(C26,'СУБД АСУТП'!1:1,0)+2,1,1,"СУБД АСУТП")),"") | J26: =IF(AND(A26=TRUE,'Тип разраб-ой док-ции'!$J$4=1),ROUNDUP(IF($F$5 =1,AF18,IF($F$5=2,AG18,IF($F$5 =3,AH18,"-")))/8,2),"-") -> #REF! | K26: =IF(AND(A26=TRUE,'Тип разраб-ой док-ции'!$J$3=1),ROUNDUP(IF($F$5 =1,AI18,IF($F$5=2,AJ18,IF($F$5 =3,AK18,"-")))/8,2),"-") -> #REF! | L26: =IF(AND(A26=TRUE,'Тип разраб-ой док-ции'!$J$2=1),ROUNDUP(IF($F$5 =1,AL18,IF($F$5=2,AM18,IF($F$5 =3,AN18,"-")))/8,2),"-") -> #REF! | M26: =IF(AND(A26=TRUE,'Тип разраб-ой док-ции'!$J$5=1),ROUNDUP(IF($F$5 =1,AO18,IF($F$5=2,AP18,IF($F$5 =3,AQ18,"-")))/8,2),"-") -> #REF! | N26: =SUM('Итоговый расчет АСУТП'!DS4:DS41) -> 0 | O26: ='АЗ АСУТП'!D$2 -> АЗ Кол-во серверных компонентов | P26: =E16 -> 0 | S26: РД | AA26: 1 | AE26: =IF(A34,MATCH(C34,'Документы АСУТП'!$E$3:$CU$3,0),"") + 4 -> #VALUE! | AF26: =INDIRECT(ADDRESS(107,AE26,1,1,"Документы АСУТП")) -> #VALUE! | AG26: =INDIRECT(ADDRESS(108,AE26,1,1,"Документы АСУТП")) -> #VALUE! | AH26: =INDIRECT(ADDRESS(109,AE26,1,1,"Документы АСУТП")) -> #VALUE! | AI26: =INDIRECT(ADDRESS(110,$AE26,1,1,"Документы АСУТП")) -> #VALUE! | AJ26: =INDIRECT(ADDRESS(111,$AE26,1,1,"Документы АСУТП")) -> #VALUE! | AK26: =INDIRECT(ADDRESS(112,$AE26,1,1,"Документы АСУТП")) -> #VALUE! | AL26: =INDIRECT(ADDRESS(113,$AE26,1,1,"Документы АСУТП")) -> #VALUE! | AM26: =INDIRECT(ADDRESS(114,$AE26,1,1,"Документы АСУТП")) -> #VALUE! | AN26: =INDIRECT(ADDRESS(115,$AE26,1,1,"Документы АСУТП")) -> #VALUE! | AO26: =INDIRECT(ADDRESS(116,$AE26,1,1,"Документы АСУТП")) -> #VALUE! | AP26: =INDIRECT(ADDRESS(117,$AE26,1,1,"Документы АСУТП")) -> #VALUE! | AQ26: =INDIRECT(ADDRESS(118,$AE26,1,1,"Документы АСУТП")) -> #VALUE!
A27: FALSE | B27: =IF(A27, "Платформа взаимодействия с главным центром ГосСОПКА","") | D27: =IF(A27,INDIRECT(ADDRESS(2,MATCH(C27,'ГОССОПКА АСУТП'!1:1),1,1,"ГОССОПКА АСУТП")),"") | F27: =IF(A27,INDIRECT(ADDRESS(2,MATCH(C27,'ГОССОПКА АСУТП'!1:1)+1,1,1,"ГОССОПКА АСУТП")),"") | H27: =IF(A27,INDIRECT(ADDRESS(2,MATCH(C27,'ГОССОПКА АСУТП'!1:1)+2,1,1,"ГОССОПКА АСУТП")),"") | J27: =IF(AND(A27=TRUE,'Тип разраб-ой док-ции'!$J$4=1),ROUNDUP(IF($F$5 =1,AF19,IF($F$5=2,AG19,IF($F$5 =3,AH19,"-")))/8,2),"-") -> #REF! | K27: =IF(AND(A27=TRUE,'Тип разраб-ой док-ции'!$J$3=1),ROUNDUP(IF($F$5 =1,AI19,IF($F$5=2,AJ19,IF($F$5 =3,AK19,"-")))/8,2),"-") -> #REF! | L27: =IF(AND(A27=TRUE,'Тип разраб-ой док-ции'!$J$2=1),ROUNDUP(IF($F$5 =1,AL19,IF($F$5=2,AM19,IF($F$5 =3,AN19,"-")))/8,2),"-") -> #REF! | M27: =IF(AND(A27=TRUE,'Тип разраб-ой док-ции'!$J$5=1),ROUNDUP(IF($F$5 =1,AO19,IF($F$5=2,AP19,IF($F$5 =3,AQ19,"-")))/8,2),"-") -> #REF! | N27: =SUM('Итоговый расчет АСУТП'!DU4:DU41) -> 0 | O27: ='АЗ АСУТП'!E$2 -> АЗ Кол-во профилей | P27: =G16 -> 0 | R27: 1 | S27: Спецификация оборудования | T27: =ROUNDUP('Итоговый расчет АСУТП'!EZ20/8,2) -> #REF! | AA27: 1 | AE27: =IF(A35,MATCH(C35,'Документы АСУТП'!$E$3:$CU$3,0),"") + 4 -> #VALUE! | AF27: =INDIRECT(ADDRESS(107,AE27,1,1,"Документы АСУТП")) -> #VALUE! | AG27: =INDIRECT(ADDRESS(108,AE27,1,1,"Документы АСУТП")) -> #VALUE! | AH27: =INDIRECT(ADDRESS(109,AE27,1,1,"Документы АСУТП")) -> #VALUE! | AI27: =INDIRECT(ADDRESS(110,$AE27,1,1,"Документы АСУТП")) -> #VALUE! | AJ27: =INDIRECT(ADDRESS(111,$AE27,1,1,"Документы АСУТП")) -> #VALUE! | AK27: =INDIRECT(ADDRESS(112,$AE27,1,1,"Документы АСУТП")) -> #VALUE! | AL27: =INDIRECT(ADDRESS(113,$AE27,1,1,"Документы АСУТП")) -> #VALUE! | AM27: =INDIRECT(ADDRESS(114,$AE27,1,1,"Документы АСУТП")) -> #VALUE! | AN27: =INDIRECT(ADDRESS(115,$AE27,1,1,"Документы АСУТП")) -> #VALUE! | AO27: =INDIRECT(ADDRESS(116,$AE27,1,1,"Документы АСУТП")) -> #VALUE! | AP27: =INDIRECT(ADDRESS(117,$AE27,1,1,"Документы АСУТП")) -> #VALUE! | AQ27: =INDIRECT(ADDRESS(118,$AE27,1,1,"Документы АСУТП")) -> #VALUE!
A28: FALSE | B28: =IF(A28, "TLS шлюз","") | D28: =IF(A28,INDIRECT(ADDRESS(2,MATCH(C28,'TLS АСУТП'!1:1),1,1,"TLS АСУТП")),"") | F28: =IF(A28,INDIRECT(ADDRESS(2,MATCH(C28,'TLS АСУТП'!1:1,0)+1,1,1,"TLS АСУТП")),"") | H28: =IF(A28,INDIRECT(ADDRESS(2,MATCH(C28,'TLS АСУТП'!1:1)+2,1,1,"TLS АСУТП")),"") | J28: =IF(AND(A28=TRUE,'Тип разраб-ой док-ции'!$J$4=1),ROUNDUP(IF($F$5 =1,AF20,IF($F$5=2,AG20,IF($F$5 =3,AH20,"-")))/8,2),"-") -> #REF! | K28: =IF(AND(A28=TRUE,'Тип разраб-ой док-ции'!$J$3=1),ROUNDUP(IF($F$5 =1,AI20,IF($F$5=2,AJ20,IF($F$5 =3,AK20,"-")))/8,2),"-") -> #REF! | L28: =IF(AND(A28=TRUE,'Тип разраб-ой док-ции'!$J$2=1),ROUNDUP(IF($F$5 =1,AL20,IF($F$5=2,AM20,IF($F$5 =3,AN20,"-")))/8,2),"-") -> #REF! | M28: =IF(AND(A28=TRUE,'Тип разраб-ой док-ции'!$J$5=1),ROUNDUP(IF($F$5 =1,AO20,IF($F$5=2,AP20,IF($F$5 =3,AQ20,"-")))/8,2),"-") -> #REF! | N28: =SUM('Итоговый расчет АСУТП'!DW4:DW41) -> 0 | O28: ='АЗ АСУТП'!F$2 -> АЗ Кол-во сканируемых узлов | P28: =I16 -> 0 | R28: 1 | S28: Инструкция по установке и настройке | T28: =ROUNDUP('Итоговый расчет АСУТП'!EZ21/8,2) -> #REF! | AA28: 0 | AE28: =IF(A36,MATCH(C36,'Документы АСУТП'!$E$3:$CU$3,0),"") + 4 -> #VALUE! | AF28: =INDIRECT(ADDRESS(107,AE28,1,1,"Документы АСУТП")) -> #VALUE! | AG28: =INDIRECT(ADDRESS(108,AE28,1,1,"Документы АСУТП")) -> #VALUE! | AH28: =INDIRECT(ADDRESS(109,AE28,1,1,"Документы АСУТП")) -> #VALUE! | AI28: =INDIRECT(ADDRESS(110,$AE28,1,1,"Документы АСУТП")) -> #VALUE! | AJ28: =INDIRECT(ADDRESS(111,$AE28,1,1,"Документы АСУТП")) -> #VALUE! | AK28: =INDIRECT(ADDRESS(112,$AE28,1,1,"Документы АСУТП")) -> #VALUE! | AL28: =INDIRECT(ADDRESS(113,$AE28,1,1,"Документы АСУТП")) -> #VALUE! | AM28: =INDIRECT(ADDRESS(114,$AE28,1,1,"Документы АСУТП")) -> #VALUE! | AN28: =INDIRECT(ADDRESS(115,$AE28,1,1,"Документы АСУТП")) -> #VALUE! | AO28: =INDIRECT(ADDRESS(116,$AE28,1,1,"Документы АСУТП")) -> #VALUE! | AP28: =INDIRECT(ADDRESS(117,$AE28,1,1,"Документы АСУТП")) -> #VALUE! | AQ28: =INDIRECT(ADDRESS(118,$AE28,1,1,"Документы АСУТП")) -> #VALUE!
A29: FALSE | B29: =IF(A29, "DCAP / DAG","") | D29: =IF(A29,INDIRECT(ADDRESS(2,MATCH(C29,'DCAP АСУТП'!1:1),1,1,"DCAP АСУТП")),"") | F29: =IF(A29,INDIRECT(ADDRESS(2,MATCH(C29,'DCAP АСУТП'!1:1)+1,1,1,"DCAP АСУТП")),"") | H29: =IF(A29,INDIRECT(ADDRESS(2,MATCH(C29,'DCAP АСУТП'!1:1)+2,1,1,"DCAP АСУТП")),"") | J29: =IF(AND(A29=TRUE,'Тип разраб-ой док-ции'!$J$4=1),ROUNDUP(IF($F$5 =1,AF21,IF($F$5=2,AG21,IF($F$5 =3,AH21,"-")))/8,2),"-") -> #REF! | K29: =IF(AND(A29=TRUE,'Тип разраб-ой док-ции'!$J$3=1),ROUNDUP(IF($F$5 =1,AI21,IF($F$5=2,AJ21,IF($F$5 =3,AK21,"-")))/8,2),"-") -> #REF! | L29: =IF(AND(A29=TRUE,'Тип разраб-ой док-ции'!$J$2=1),ROUNDUP(IF($F$5 =1,AL21,IF($F$5=2,AM21,IF($F$5 =3,AN21,"-")))/8,2),"-") -> #REF! | M29: =IF(AND(A29=TRUE,'Тип разраб-ой док-ции'!$J$5=1),ROUNDUP(IF($F$5 =1,AO21,IF($F$5=2,AP21,IF($F$5 =3,AQ21,"-")))/8,2),"-") -> #REF! | N29: =SUM('Итоговый расчет АСУТП'!DY4:DY41) -> 0 | O29: ='РК АСУТП'!D$2 -> РК Кол-во площадок с серверными компонентами | P29: =E17 -> 0 | R29: - | S29: Схема соединений внешних проводок | T29: =ROUNDUP('Итоговый расчет АСУТП'!EZ22/8,2) -> 0 | AA29: 1 | AE29: =IF(A37,MATCH(C37,'Документы АСУТП'!$E$3:$CU$3,0),"") + 4 -> #VALUE! | AF29: =INDIRECT(ADDRESS(107,AE29,1,1,"Документы АСУТП")) -> #VALUE! | AG29: =INDIRECT(ADDRESS(108,AE29,1,1,"Документы АСУТП")) -> #VALUE! | AH29: =INDIRECT(ADDRESS(109,AE29,1,1,"Документы АСУТП")) -> #VALUE! | AI29: =INDIRECT(ADDRESS(110,$AE29,1,1,"Документы АСУТП")) -> #VALUE! | AJ29: =INDIRECT(ADDRESS(111,$AE29,1,1,"Документы АСУТП")) -> #VALUE! | AK29: =INDIRECT(ADDRESS(112,$AE29,1,1,"Документы АСУТП")) -> #VALUE! | AL29: =INDIRECT(ADDRESS(113,$AE29,1,1,"Документы АСУТП")) -> #VALUE! | AM29: =INDIRECT(ADDRESS(114,$AE29,1,1,"Документы АСУТП")) -> #VALUE! | AN29: =INDIRECT(ADDRESS(115,$AE29,1,1,"Документы АСУТП")) -> #VALUE! | AO29: =INDIRECT(ADDRESS(116,$AE29,1,1,"Документы АСУТП")) -> #VALUE! | AP29: =INDIRECT(ADDRESS(117,$AE29,1,1,"Документы АСУТП")) -> #VALUE! | AQ29: =INDIRECT(ADDRESS(118,$AE29,1,1,"Документы АСУТП")) -> #VALUE!
A30: FALSE | B30: =IF(A30, "Контроль конфигураций","") | D30: =IF(A30,INDIRECT(ADDRESS(2,MATCH(C30,'DO АСУТП'!1:1),1,1,"КОНФИГ АСУТП")),"") | F30: =IF(A30,INDIRECT(ADDRESS(2,MATCH(C30,'DO АСУТП'!1:1)+1,1,1,"КОНФИГ АСУТП")),"") | H30: =IF(A30,INDIRECT(ADDRESS(2,MATCH(C30,'DO АСУТП'!1:1)+2,1,1,"КОНФИГ АСУТП")),"") | J30: =IF(AND(A30=TRUE,'Тип разраб-ой док-ции'!$J$4=1),ROUNDUP(IF($F$5 =1,AF22,IF($F$5=2,AG22,IF($F$5 =3,AH22,"-")))/8,2),"-") -> #REF! | K30: =IF(AND(A30=TRUE,'Тип разраб-ой док-ции'!$J$3=1),ROUNDUP(IF($F$5 =1,AI22,IF($F$5=2,AJ22,IF($F$5 =3,AK22,"-")))/8,2),"-") -> #REF! | L30: =IF(AND(A30=TRUE,'Тип разраб-ой док-ции'!$J$2=1),ROUNDUP(IF($F$5 =1,AL22,IF($F$5=2,AM22,IF($F$5 =3,AN22,"-")))/8,2),"-") -> #REF! | M30: =IF(AND(A30=TRUE,'Тип разраб-ой док-ции'!$J$5=1),ROUNDUP(IF($F$5 =1,AO22,IF($F$5=2,AP22,IF($F$5 =3,AQ22,"-")))/8,2),"-") -> #REF! | N30: =SUM('Итоговый расчет АСУТП'!EA4:EA41) -> 0 | O30: ='РК АСУТП'!E$2 -> РК Кол-во типов целевых систем для РК | P30: =G17 -> 0 | R30: - | S30: Таблица соединений и подключений | T30: =ROUNDUP('Итоговый расчет АСУТП'!EZ23/8,2) -> 0 | AA30: 1 | AE30: =IF(A38,MATCH(C38,'Документы АСУТП'!$E$3:$CU$3,0),"") + 4 -> #VALUE! | AF30: =INDIRECT(ADDRESS(107,AE30,1,1,"Документы АСУТП")) -> #VALUE! | AG30: =INDIRECT(ADDRESS(108,AE30,1,1,"Документы АСУТП")) -> #VALUE! | AH30: =INDIRECT(ADDRESS(109,AE30,1,1,"Документы АСУТП")) -> #VALUE! | AI30: =INDIRECT(ADDRESS(110,$AE30,1,1,"Документы АСУТП")) -> #VALUE! | AJ30: =INDIRECT(ADDRESS(111,$AE30,1,1,"Документы АСУТП")) -> #VALUE! | AK30: =INDIRECT(ADDRESS(112,$AE30,1,1,"Документы АСУТП")) -> #VALUE! | AL30: =INDIRECT(ADDRESS(113,$AE30,1,1,"Документы АСУТП")) -> #VALUE! | AM30: =INDIRECT(ADDRESS(114,$AE30,1,1,"Документы АСУТП")) -> #VALUE! | AN30: =INDIRECT(ADDRESS(115,$AE30,1,1,"Документы АСУТП")) -> #VALUE! | AO30: =INDIRECT(ADDRESS(116,$AE30,1,1,"Документы АСУТП")) -> #VALUE! | AP30: =INDIRECT(ADDRESS(117,$AE30,1,1,"Документы АСУТП")) -> #VALUE! | AQ30: =INDIRECT(ADDRESS(118,$AE30,1,1,"Документы АСУТП")) -> #VALUE!
